Workbook

Sheet 入力
B1: 法人 役員報酬シミュレーション【入力シート】
B2: このシートの黄色いセルに数値を入力すると、「シミュレーション1」〜「シミュレーション5」シートが自動で再計算されます。役員が複数いる場合は「役員の人数」を変更し、役員2以降の前提条件も入力してください。E列の「配偶者の給与収入」行に表示される金額は配偶者の合計所得金額の自動計算結果(入力不要)です。
B4: 【会社の前提条件】
B5: 税引前利益（役員報酬控除前・年額） | C5: 20000000 | D5: 役員報酬を1円も払わなかった場合に法人に残る年間利益（減価償却等調整後）
B6: 資本金 | C6: 10000000 | D6: 1億円以下の中小法人を想定した実効税率をデフォルト設定しています
B7: 役員の人数 | C7: 1 | D7: 2人以上の場合、下記の役員2〜5の前提条件欄も入力してください。人数を超える役員欄は自動的に集計から除外されます
B9: 【役員1の前提条件】
B10: 年齢区分 | C10: 40歳未満 | D10: 40歳以上64歳以下は介護保険料（第2号被保険者）が加算されます
B11: 配偶者の有無 | C11: 有 | D11: 配偶者控除の判定に使用
B12: 配偶者の給与収入（年間） | C12: 0 | D12: 136万円以下は配偶者控除、136万円超207万円以下は配偶者特別控除（段階的に減額）、207万円超は対象外（令和8・9年分） | E12: =IF(C12<=0,0,MAX(C12-IF(C12<=2200000,740000,IF(C12<=3600000,C12*0.3+80000,IF(C12<=6600000,C12*0.2+440000,IF(C12<=8500000,C12*0.1+1100000,1950000)))),0))
B13: 一般の扶養親族の数 | C13: 0 | D13: 16～18歳・23～69歳（同居老親等を除く）
B14: 特定扶養親族の数 | C14: 0 | D14: 19～22歳（特定親族特別控除の対象は下記で別途入力）
B15: うち収入がある特定親族の人数 | C15: 0 | D15: 合計所得62万円超123万円以下（給与収入136万円超197万円以下）で特定親族特別控除が段階的に適用されます（令和8年度改正で新設）。特定扶養親族の数を超えないようにしてください
B16: その特定親族の給与収入（年間・全員同額と仮定） | C16: 0 | E16: =IF(C16<=0,0,MAX(C16-IF(C16<=2200000,740000,IF(C16<=3600000,C16*0.3+80000,IF(C16<=6600000,C16*0.2+440000,IF(C16<=8500000,C16*0.1+1100000,1950000)))),0))
B17: 老人扶養親族の数（同居） | C17: 0 | D17: 70歳以上・同居老親等
B19: 【役員2の前提条件】
B20: 年齢区分 | C20: 40歳未満 | D20: 40歳以上64歳以下は介護保険料（第2号被保険者）が加算されます
B21: 配偶者の有無 | C21: 有 | D21: 配偶者控除の判定に使用
B22: 配偶者の給与収入（年間） | C22: 0 | D22: 136万円以下は配偶者控除、136万円超207万円以下は配偶者特別控除（段階的に減額）、207万円超は対象外（令和8・9年分） | E22: =IF(C22<=0,0,MAX(C22-IF(C22<=2200000,740000,IF(C22<=3600000,C22*0.3+80000,IF(C22<=6600000,C22*0.2+440000,IF(C22<=8500000,C22*0.1+1100000,1950000)))),0))
B23: 一般の扶養親族の数 | C23: 0 | D23: 16～18歳・23～69歳（同居老親等を除く）
B24: 特定扶養親族の数 | C24: 0 | D24: 19～22歳（特定親族特別控除の対象は下記で別途入力）
B25: うち収入がある特定親族の人数 | C25: 0 | D25: 合計所得62万円超123万円以下（給与収入136万円超197万円以下）で特定親族特別控除が段階的に適用されます（令和8年度改正で新設）。特定扶養親族の数を超えないようにしてください
B26: その特定親族の給与収入（年間・全員同額と仮定） | C26: 0 | E26: =IF(C26<=0,0,MAX(C26-IF(C26<=2200000,740000,IF(C26<=3600000,C26*0.3+80000,IF(C26<=6600000,C26*0.2+440000,IF(C26<=8500000,C26*0.1+1100000,1950000)))),0))
B27: 老人扶養親族の数（同居） | C27: 0 | D27: 70歳以上・同居老親等
B29: 【役員3の前提条件】
B30: 年齢区分 | C30: 40歳未満 | D30: 40歳以上64歳以下は介護保険料（第2号被保険者）が加算されます
B31: 配偶者の有無 | C31: 有 | D31: 配偶者控除の判定に使用
B32: 配偶者の給与収入（年間） | C32: 0 | D32: 136万円以下は配偶者控除、136万円超207万円以下は配偶者特別控除（段階的に減額）、207万円超は対象外（令和8・9年分） | E32: =IF(C32<=0,0,MAX(C32-IF(C32<=2200000,740000,IF(C32<=3600000,C32*0.3+80000,IF(C32<=6600000,C32*0.2+440000,IF(C32<=8500000,C32*0.1+1100000,1950000)))),0))
B33: 一般の扶養親族の数 | C33: 0 | D33: 16～18歳・23～69歳（同居老親等を除く）
B34: 特定扶養親族の数 | C34: 0 | D34: 19～22歳（特定親族特別控除の対象は下記で別途入力）
B35: うち収入がある特定親族の人数 | C35: 0 | D35: 合計所得62万円超123万円以下（給与収入136万円超197万円以下）で特定親族特別控除が段階的に適用されます（令和8年度改正で新設）。特定扶養親族の数を超えないようにしてください
B36: その特定親族の給与収入（年間・全員同額と仮定） | C36: 0 | E36: =IF(C36<=0,0,MAX(C36-IF(C36<=2200000,740000,IF(C36<=3600000,C36*0.3+80000,IF(C36<=6600000,C36*0.2+440000,IF(C36<=8500000,C36*0.1+1100000,1950000)))),0))
B37: 老人扶養親族の数（同居） | C37: 0 | D37: 70歳以上・同居老親等
B39: 【役員4の前提条件】
B40: 年齢区分 | C40: 40歳未満 | D40: 40歳以上64歳以下は介護保険料（第2号被保険者）が加算されます
B41: 配偶者の有無 | C41: 有 | D41: 配偶者控除の判定に使用
B42: 配偶者の給与収入（年間） | C42: 0 | D42: 136万円以下は配偶者控除、136万円超207万円以下は配偶者特別控除（段階的に減額）、207万円超は対象外（令和8・9年分） | E42: =IF(C42<=0,0,MAX(C42-IF(C42<=2200000,740000,IF(C42<=3600000,C42*0.3+80000,IF(C42<=6600000,C42*0.2+440000,IF(C42<=8500000,C42*0.1+1100000,1950000)))),0))
B43: 一般の扶養親族の数 | C43: 0 | D43: 16～18歳・23～69歳（同居老親等を除く）
B44: 特定扶養親族の数 | C44: 0 | D44: 19～22歳（特定親族特別控除の対象は下記で別途入力）
B45: うち収入がある特定親族の人数 | C45: 0 | D45: 合計所得62万円超123万円以下（給与収入136万円超197万円以下）で特定親族特別控除が段階的に適用されます（令和8年度改正で新設）。特定扶養親族の数を超えないようにしてください
...

Sheet 早見表
A1: 健康保険 標準報酬月額等級表（協会けんぽ・50等級） | F1: 厚生年金保険 標準報酬月額等級表（32等級） | K1: 所得税 速算表（課税所得ベース） | O1: 基礎控除（所得税・令和8・9年分） | R1: 固定控除額等 | U1: 配偶者控除・配偶者特別控除額（令和8・9年分） | AD1: 特定親族特別控除額（令和8・9年分）
A2: 等級 | B2: 報酬月額(以上) | C2: 報酬月額(未満) | D2: 標準報酬月額 | F2: 等級 | G2: 報酬月額(以上) | H2: 報酬月額(未満) | I2: 標準報酬月額 | K2: 課税所得(以上) | L2: 税率 | M2: 控除額 | O2: 合計所得(以上) | P2: 控除額 | R2: 基礎控除（住民税・据置き。合計所得2,400万円以下） | S2: 430000 | U2: 配偶者合計所得(以上) | V2: 所得税(900万円以下) | W2: 所得税(900-950万円) | X2: 所得税(950-1000万円) | Y2: 住民税(900万円以下) | Z2: 住民税(900-950万円) | AA2: 住民税(950-1000万円) | AD2: 特定親族合計所得(以上) | AE2: 所得税 | AF2: 住民税
A3: 1 | B3: 0 | C3: 63000 | D3: 58000 | F3: 1 | G3: 0 | H3: 93000 | I3: 88000 | K3: 0 | L3: 0.05 | M3: 0 | O3: 0 | P3: 1040000 | R3: 住民税 均等割＋森林環境税（標準額） | S3: 5000 | U3: 0 | V3: 380000 | W3: 260000 | X3: 130000 | Y3: 330000 | Z3: 220000 | AA3: 110000 | AD3: 620001 | AE3: 630000 | AF3: 450000
A4: 2 | B4: 63000 | C4: 73000 | D4: 68000 | F4: 2 | G4: 93000 | H4: 101000 | I4: 98000 | K4: 1950000 | L4: 0.1 | M4: 97500 | O4: 4890000 | P4: 670000 | R4: 住民税 所得割率 | S4: 0.1 | U4: 950001 | V4: 360000 | W4: 240000 | X4: 120000 | Y4: 330000 | Z4: 220000 | AA4: 110000 | AD4: 850001 | AE4: 610000 | AF4: 450000
A5: 3 | B5: 73000 | C5: 83000 | D5: 78000 | F5: 3 | G5: 101000 | H5: 107000 | I5: 104000 | K5: 3300000 | L5: 0.2 | M5: 427500 | O5: 6550000 | P5: 620000 | R5: 扶養控除（所得税）一般 | S5: 380000 | U5: 1000001 | V5: 310000 | W5: 210000 | X5: 110000 | Y5: 310000 | Z5: 210000 | AA5: 110000 | AD5: 900001 | AE5: 510000 | AF5: 450000
A6: 4 | B6: 83000 | C6: 93000 | D6: 88000 | F6: 4 | G6: 107000 | H6: 114000 | I6: 110000 | K6: 6950000 | L6: 0.23 | M6: 636000 | O6: 23500000 | P6: 480000 | R6: 扶養控除（所得税）特定 | S6: 630000 | U6: 1050001 | V6: 260000 | W6: 180000 | X6: 90000 | Y6: 260000 | Z6: 180000 | AA6: 90000 | AD6: 950001 | AE6: 410000 | AF6: 410000
A7: 5 | B7: 93000 | C7: 101000 | D7: 98000 | F7: 5 | G7: 114000 | H7: 122000 | I7: 118000 | K7: 9000000 | L7: 0.33 | M7: 1536000 | O7: 24000000 | P7: 320000 | R7: 扶養控除（所得税）老人同居 | S7: 580000 | U7: 1100001 | V7: 210000 | W7: 140000 | X7: 70000 | Y7: 210000 | Z7: 140000 | AA7: 70000 | AD7: 1000001 | AE7: 310000 | AF7: 310000
A8: 6 | B8: 101000 | C8: 107000 | D8: 104000 | F8: 6 | G8: 122000 | H8: 130000 | I8: 126000 | K8: 18000000 | L8: 0.4 | M8: 2796000 | O8: 24500000 | P8: 160000 | R8: 扶養控除（住民税）一般 | S8: 330000 | U8: 1150001 | V8: 160000 | W8: 110000 | X8: 60000 | Y8: 160000 | Z8: 110000 | AA8: 60000 | AD8: 1050001 | AE8: 210000 | AF8: 210000
A9: 7 | B9: 107000 | C9: 114000 | D9: 110000 | F9: 7 | G9: 130000 | H9: 138000 | I9: 134000 | K9: 40000000 | L9: 0.45 | M9: 4796000 | O9: 25000000 | P9: 0 | R9: 扶養控除（住民税）特定 | S9: 450000 | U9: 1200001 | V9: 110000 | W9: 80000 | X9: 40000 | Y9: 110000 | Z9: 80000 | AA9: 40000 | AD9: 1100001 | AE9: 110000 | AF9: 110000
A10: 8 | B10: 114000 | C10: 122000 | D10: 118000 | F10: 8 | G10: 138000 | H10: 146000 | I10: 142000 | R10: 扶養控除（住民税）老人同居 | S10: 450000 | U10: 1250001 | V10: 60000 | W10: 40000 | X10: 20000 | Y10: 60000 | Z10: 40000 | AA10: 20000 | AD10: 1150001 | AE10: 60000 | AF10: 60000
A11: 9 | B11: 122000 | C11: 130000 | D11: 126000 | F11: 9 | G11: 146000 | H11: 155000 | I11: 150000 | U11: 1300001 | V11: 30000 | W11: 20000 | X11: 10000 | Y11: 30000 | Z11: 20000 | AA11: 10000 | AD11: 1200001 | AE11: 30000 | AF11: 30000
A12: 10 | B12: 130000 | C12: 138000 | D12: 134000 | F12: 10 | G12: 155000 | H12: 165000 | I12: 160000 | U12: 1330001 | V12: 0 | W12: 0 | X12: 0 | Y12: 0 | Z12: 0 | AA12: 0 | AD12: 1230001 | AE12: 0 | AF12: 0
A13: 11 | B13: 138000 | C13: 146000 | D13: 142000 | F13: 11 | G13: 165000 | H13: 175000 | I13: 170000
A14: 12 | B14: 146000 | C14: 155000 | D14: 150000 | F14: 12 | G14: 175000 | H14: 185000 | I14: 180000
A15: 13 | B15: 155000 | C15: 165000 | D15: 160000 | F15: 13 | G15: 185000 | H15: 195000 | I15: 190000
A16: 14 | B16: 165000 | C16: 175000 | D16: 170000 | F16: 14 | G16: 195000 | H16: 210000 | I16: 200000
A17: 15 | B17: 175000 | C17: 185000 | D17: 180000 | F17: 15 | G17: 210000 | H17: 230000 | I17: 220000
A18: 16 | B18: 185000 | C18: 195000 | D18: 190000 | F18: 16 | G18: 230000 | H18: 250000 | I18: 240000
A19: 17 | B19: 195000 | C19: 210000 | D19: 200000 | F19: 17 | G19: 250000 | H19: 270000 | I19: 260000
A20: 18 | B20: 210000 | C20: 230000 | D20: 220000 | F20: 18 | G20: 270000 | H20: 290000 | I20: 280000
A21: 19 | B21: 230000 | C21: 250000 | D21: 240000 | F21: 19 | G21: 290000 | H21: 310000 | I21: 300000
A22: 20 | B22: 250000 | C22: 270000 | D22: 260000 | F22: 20 | G22: 310000 | H22: 330000 | I22: 320000
A23: 21 | B23: 270000 | C23: 290000 | D23: 280000 | F23: 21 | G23: 330000 | H23: 350000 | I23: 340000
A24: 22 | B24: 290000 | C24: 310000 | D24: 300000 | F24: 22 | G24: 350000 | H24: 370000 | I24: 360000
... A33: 31 | B33: 515000 | C33: 545000 | D33: 530000 | F33: 31 | G33: 605000 | H33: 635000 | I33: 620000
A34: 32 | B34: 545000 | C34: 575000 | D34: 560000 | F34: 32 | G34: 635000 | H34: － | I34: 650000
A35: 33 | B35: 575000 | C35: 605000 | D35: 590000
A36: 34 | B36: 605000 | C36: 635000 | D36: 620000
A37: 35 | B37: 635000 | C37: 665000 | D37: 650000
A38: 36 | B38: 665000 | C38: 695000 | D38: 680000
A39: 37 | B39: 695000 | C39: 730000 | D39: 710000
A40: 38 | B40: 730000 | C40: 770000 | D40: 750000
A41: 39 | B41: 770000 | C41: 810000 | D41: 790000
A42: 40 | B42: 810000 | C42: 855000 | D42: 830000
A43: 41 | B43: 855000 | C43: 905000 | D43: 880000
A44: 42 | B44: 905000 | C44: 955000 | D44: 930000
A45: 43 | B45: 955000 | C45: 1005000 | D45: 980000
A46: 44 | B46: 1005000 | C46: 1055000 | D46: 1030000
... A51: 49 | B51: 1295000 | C51: 1355000 | D51: 1330000
A52: 50 | B52: 1355000 | C52: － | D52: 1390000

Sheet シミュレーション1
A1: # | B1: 役員報酬(年額) | C1: 役員報酬(月額) | D1: 標準報酬月額(健保) | E1: 標準報酬月額(厚年) | F1: 社会保険料(個人負担) | G1: 社会保険料(会社負担) | H1: 給与所得控除 | I1: 給与所得 | J1: 所得控除合計(所得税) | K1: 課税所得(所得税) | L1: 所得税 | M1: 復興特別所得税 | N1: 所得税等合計 | O1: 住民税(所得割) | P1: 住民税(均等割等) | Q1: 住民税合計 | R1: 個人負担合計 | S1: 個人手取り額 | T1: 個人手取り率 | U1: 会社コスト(この役員の報酬+法定福利費) | V1: 役員報酬控除後利益(全役員ベース) | W1: 法人税等 | X1: 内部留保(税引後) | Y1: トータル手取り(内部留保+個人手取り合計) | Z1: 実効負担率(対税引前利益)
A2: 1 | B2: ='入力'!$C$69 | C2: =IF($B2="","",$B2/12) | D2: =IF($B2="","",IF($B2=0,0,VLOOKUP($C2,'早見表'!$B$3:$D$52,3,TRUE()))) | E2: =IF($B2="","",IF($B2=0,0,VLOOKUP($C2,'早見表'!$G$3:$I$34,3,TRUE()))) | F2: =IF($B2="","",ROUND($D2*('入力'!$C$60+IF('入力'!$C$10="40歳以上64歳以下",'入力'!$C$61,0))/2*12,0)+ROUND($E2*'入力'!$C$62/2*12,0)+ROUND($D2*'入力'!$C$64/2*12,0)) | G2: =IF($B2="","",ROUND($D2*('入力'!$C$60+IF('入力'!$C$10="40歳以上64歳以下",'入力'!$C$61,0))/2*12,0)+ROUND($E2*'入力'!$C$62/2*12,0)+ROUND($E2*'入力'!$C$63*12,0)+ROUND($D2*'入力'!$C$64/2*12,0)) | H2: =IF($B2="","",IF($B2<=2200000,740000,IF($B2<=3600000,$B2*0.3+80000,IF($B2<=6600000,$B2*0.2+440000,IF($B2<=8500000,$B2*0.1+1100000,1950000))))) | I2: =IF($B2="","",MAX($B2-$H2,0)) | J2: =IF($B2="","",$F2+VLOOKUP($I2,'早見表'!$O$3:$P$9,2,TRUE())+IF(AND('入力'!$C$11="有",$I2<=10000000),VLOOKUP('入力'!$E$12,'早見表'!$U$3:$AA$12,IF($I2<=9000000,2,IF($I2<=9500000,3,4)),TRUE()),0)+'入力'!$C$13*'早見表'!$S$5+MAX('入力'!$C$14-'入力'!$C$15,0)*'早見表'!$S$6+IF('入力'!$C$15<=0,0,IF('入力'!$E$16<620001,630000,VLOOKUP('入力'!$E$16,'早見表'!$AD$3:$AF$12,2,TRUE()))*'入力'!$C$15)+'入力'!$C$17*'早見表'!$S$7) | K2: =IF($B2="","",ROUNDDOWN(MAX($I2-$J2,0),-3)) | L2: =IF($B2="","",ROUNDDOWN(MAX($K2*VLOOKUP($K2,'早見表'!$K$3:$M$9,2,TRUE())-VLOOKUP($K2,'早見表'!$K$3:$M$9,3,TRUE()),0),0)) | M2: =IF($B2="","",ROUNDDOWN($L2*0.021,0)) | N2: =IF($B2="","",$L2+$M2) | O2: =IF($B2="","",ROUNDDOWN(MAX($I2-($F2+'早見表'!$S$2+IF(AND('入力'!$C$11="有",$I2<=10000000),VLOOKUP('入力'!$E$12,'早見表'!$U$3:$AA$12,IF($I2<=9000000,5,IF($I2<=9500000,6,7)),TRUE()),0)+'入力'!$C$13*'早見表'!$S$8+MAX('入力'!$C$14-'入力'!$C$15,0)*'早見表'!$S$9+IF('入力'!$C$15<=0,0,IF('入力'!$E$16<620001,450000,VLOOKUP('入力'!$E$16,'早見表'!$AD$3:$AF$12,3,TRUE()))*'入力'!$C$15)+'入力'!$C$17*'早見表'!$S$10),0),-3)*'早見表'!$S$4) | P2: =IF($B2="","",'早見表'!$S$3) | Q2: =IF($B2="","",$O2+$P2) | R2: =IF($B2="","",$F2+$N2+$Q2) | S2: =IF($B2="","",$B2-$R2) | T2: =IF($B2="","",IF($B2=0,"",$S2/$B2)) | U2: =IF($B2="","",$B2+$G2) | V2: =IF($B2="","",'入力'!$C$5-$U2-('結果サマリー'!$C$23-'結果サマリー'!$C$7)) | W2: =IF($B2="","",IF($V2<=0,0,IF($V2<=8000000,$V2*'入力'!$C$65,8000000*'入力'!$C$65+($V2-8000000)*'入力'!$C$66))) | X2: =IF($B2="","",$V2-$W2) | Y2: =IF($B2="","",$X2+$S2+('結果サマリー'!$C$27-'結果サマリー'!$C$6)) | Z2: =IF($B2="","",IF('入力'!$C$5=0,"",1-$Y2/'入力'!$C$5))
A3: 2 | B3: =IF(B2="","",IF(B2+'入力'!$C$71>'入力'!$C$70,"",B2+'入力'!$C$71)) | C3: =IF($B3="","",$B3/12) | D3: =IF($B3="","",IF($B3=0,0,VLOOKUP($C3,'早見表'!$B$3:$D$52,3,TRUE()))) | E3: =IF($B3="","",IF($B3=0,0,VLOOKUP($C3,'早見表'!$G$3:$I$34,3,TRUE()))) | F3: =IF($B3="","",ROUND($D3*('入力'!$C$60+IF('入力'!$C$10="40歳以上64歳以下",'入力'!$C$61,0))/2*12,0)+ROUND($E3*'入力'!$C$62/2*12,0)+ROUND($D3*'入力'!$C$64/2*12,0)) | G3: =IF($B3="","",ROUND($D3*('入力'!$C$60+IF('入力'!$C$10="40歳以上64歳以下",'入力'!$C$61,0))/2*12,0)+ROUND($E3*'入力'!$C$62/2*12,0)+ROUND($E3*'入力'!$C$63*12,0)+ROUND($D3*'入力'!$C$64/2*12,0)) | H3: =IF($B3="","",IF($B3<=2200000,740000,IF($B3<=3600000,$B3*0.3+80000,IF($B3<=6600000,$B3*0.2+440000,IF($B3<=8500000,$B3*0.1+1100000,1950000))))) | I3: =IF($B3="","",MAX($B3-$H3,0)) | J3: =IF($B3="","",$F3+VLOOKUP($I3,'早見表'!$O$3:$P$9,2,TRUE())+IF(AND('入力'!$C$11="有",$I3<=10000000),VLOOKUP('入力'!$E$12,'早見表'!$U$3:$AA$12,IF($I3<=9000000,2,IF($I3<=9500000,3,4)),TRUE()),0)+'入力'!$C$13*'早見表'!$S$5+MAX('入力'!$C$14-'入力'!$C$15,0)*'早見表'!$S$6+IF('入力'!$C$15<=0,0,IF('入力'!$E$16<620001,630000,VLOOKUP('入力'!$E$16,'早見表'!$AD$3:$AF$12,2,TRUE()))*'入力'!$C$15)+'入力'!$C$17*'早見表'!$S$7) | K3: =IF($B3="","",ROUNDDOWN(MAX($I3-$J3,0),-3)) | L3: =IF($B3="","",ROUNDDOWN(MAX($K3*VLOOKUP($K3,'早見表'!$K$3:$M$9,2,TRUE())-VLOOKUP($K3,'早見表'!$K$3:$M$9,3,TRUE()),0),0)) | M3: =IF($B3="","",ROUNDDOWN($L3*0.021,0)) | N3: =IF($B3="","",$L3+$M3) | O3: =IF($B3="","",ROUNDDOWN(MAX($I3-($F3+'早見表'!$S$2+IF(AND('入力'!$C$11="有",$I3<=10000000),VLOOKUP('入力'!$E$12,'早見表'!$U$3:$AA$12,IF($I3<=9000000,5,IF($I3<=9500000,6,7)),TRUE()),0)+'入力'!$C$13*'早見表'!$S$8+MAX('入力'!$C$14-'入力'!$C$15,0)*'早見表'!$S$9+IF('入力'!$C$15<=0,0,IF('入力'!$E$16<620001,450000,VLOOKUP('入力'!$E$16,'早見表'!$AD$3:$AF$12,3,TRUE()))*'入力'!$C$15)+'入力'!$C$17*'早見表'!$S$10),0),-3)*'早見表'!$S$4) | P3: =IF($B3="","",'早見表'!$S$3) | Q3: =IF($B3="","",$O3+$P3) | R3: =IF($B3="","",$F3+$N3+$Q3) | S3: =IF($B3="","",$B3-$R3) | T3: =IF($B3="","",IF($B3=0,"",$S3/$B3)) | U3: =IF($B3="","",$B3+$G3) | V3: =IF($B3="","",'入力'!$C$5-$U3-('結果サマリー'!$C$23-'結果サマリー'!$C$7)) | W3: =IF($B3="","",IF($V3<=0,0,IF($V3<=8000000,$V3*'入力'!$C$65,8000000*'入力'!$C$65+($V3-8000000)*'入力'!$C$66))) | X3: =IF($B3="","",$V3-$W3) | Y3: =IF($B3="","",$X3+$S3+('結果サマリー'!$C$27-'結果サマリー'!$C$6)) | Z3: =IF($B3="","",IF('入力'!$C$5=0,"",1-$Y3/'入力'!$C$5))
A4: 3 | B4: =IF(B3="","",IF(B3+'入力'!$C$71>'入力'!$C$70,"",B3+'入力'!$C$71)) | C4: =IF($B4="","",$B4/12) | D4: =IF($B4="","",IF($B4=0,0,VLOOKUP($C4,'早見表'!$B$3:$D$52,3,TRUE()))) | E4: =IF($B4="","",IF($B4=0,0,VLOOKUP($C4,'早見表'!$G$3:$I$34,3,TRUE()))) | F4: =IF($B4="","",ROUND($D4*('入力'!$C$60+IF('入力'!$C$10="40歳以上64歳以下",'入力'!$C$61,0))/2*12,0)+ROUND($E4*'入力'!$C$62/2*12,0)+ROUND($D4*'入力'!$C$64/2*12,0)) | G4: =IF($B4="","",ROUND($D4*('入力'!$C$60+IF('入力'!$C$10="40歳以上64歳以下",'入力'!$C$61,0))/2*12,0)+ROUND($E4*'入力'!$C$62/2*12,0)+ROUND($E4*'入力'!$C$63*12,0)+ROUND($D4*'入力'!$C$64/2*12,0)) | H4: =IF($B4="","",IF($B4<=2200000,740000,IF($B4<=3600000,$B4*0.3+80000,IF($B4<=6600000,$B4*0.2+440000,IF($B4<=8500000,$B4*0.1+1100000,1950000))))) | I4: =IF($B4="","",MAX($B4-$H4,0)) | J4: =IF($B4="","",$F4+VLOOKUP($I4,'早見表'!$O$3:$P$9,2,TRUE())+IF(AND('入力'!$C$11="有",$I4<=10000000),VLOOKUP('入力'!$E$12,'早見表'!$U$3:$AA$12,IF($I4<=9000000,2,IF($I4<=9500000,3,4)),TRUE()),0)+'入力'!$C$13*'早見表'!$S$5+MAX('入力'!$C$14-'入力'!$C$15,0)*'早見表'!$S$6+IF('入力'!$C$15<=0,0,IF('入力'!$E$16<620001,630000,VLOOKUP('入力'!$E$16,'早見表'!$AD$3:$AF$12,2,TRUE()))*'入力'!$C$15)+'入力'!$C$17*'早見表'!$S$7) | K4: =IF($B4="","",ROUNDDOWN(MAX($I4-$J4,0),-3)) | L4: =IF($B4="","",ROUNDDOWN(MAX($K4*VLOOKUP($K4,'早見表'!$K$3:$M$9,2,TRUE())-VLOOKUP($K4,'早見表'!$K$3:$M$9,3,TRUE()),0),0)) | M4: =IF($B4="","",ROUNDDOWN($L4*0.021,0)) | N4: =IF($B4="","",$L4+$M4) | O4: =IF($B4="","",ROUNDDOWN(MAX($I4-($F4+'早見表'!$S$2+IF(AND('入力'!$C$11="有",$I4<=10000000),VLOOKUP('入力'!$E$12,'早見表'!$U$3:$AA$12,IF($I4<=9000000,5,IF($I4<=9500000,6,7)),TRUE()),0)+'入力'!$C$13*'早見表'!$S$8+MAX('入力'!$C$14-'入力'!$C$15,0)*'早見表'!$S$9+IF('入力'!$C$15<=0,0,IF('入力'!$E$16<620001,450000,VLOOKUP('入力'!$E$16,'早見表'!$AD$3:$AF$12,3,TRUE()))*'入力'!$C$15)+'入力'!$C$17*'早見表'!$S$10),0),-3)*'早見表'!$S$4) | P4: =IF($B4="","",'早見表'!$S$3) | Q4: =IF($B4="","",$O4+$P4) | R4: =IF($B4="","",$F4+$N4+$Q4) | S4: =IF($B4="","",$B4-$R4) | T4: =IF($B4="","",IF($B4=0,"",$S4/$B4)) | U4: =IF($B4="","",$B4+$G4) | V4: =IF($B4="","",'入力'!$C$5-$U4-('結果サマリー'!$C$23-'結果サマリー'!$C$7)) | W4: =IF($B4="","",IF($V4<=0,0,IF($V4<=8000000,$V4*'入力'!$C$65,8000000*'入力'!$C$65+($V4-8000000)*'入力'!$C$66))) | X4: =IF($B4="","",$V4-$W4) | Y4: =IF($B4="","",$X4+$S4+('結果サマリー'!$C$27-'結果サマリー'!$C$6)) | Z4: =IF($B4="","",IF('入力'!$C$5=0,"",1-$Y4/'入力'!$C$5))
A5: 4 | B5: =IF(B4="","",IF(B4+'入力'!$C$71>'入力'!$C$70,"",B4+'入力'!$C$71)) | C5: =IF($B5="","",$B5/12) | D5: =IF($B5="","",IF($B5=0,0,VLOOKUP($C5,'早見表'!$B$3:$D$52,3,TRUE()))) | E5: =IF($B5="","",IF($B5=0,0,VLOOKUP($C5,'早見表'!$G$3:$I$34,3,TRUE()))) | F5: =IF($B5="","",ROUND($D5*('入力'!$C$60+IF('入力'!$C$10="40歳以上64歳以下",'入力'!$C$61,0))/2*12,0)+ROUND($E5*'入力'!$C$62/2*12,0)+ROUND($D5*'入力'!$C$64/2*12,0)) | G5: =IF($B5="","",ROUND($D5*('入力'!$C$60+IF('入力'!$C$10="40歳以上64歳以下",'入力'!$C$61,0))/2*12,0)+ROUND($E5*'入力'!$C$62/2*12,0)+ROUND($E5*'入力'!$C$63*12,0)+ROUND($D5*'入力'!$C$64/2*12,0)) | H5: =IF($B5="","",IF($B5<=2200000,740000,IF($B5<=3600000,$B5*0.3+80000,IF($B5<=6600000,$B5*0.2+440000,IF($B5<=8500000,$B5*0.1+1100000,1950000))))) | I5: =IF($B5="","",MAX($B5-$H5,0)) | J5: =IF($B5="","",$F5+VLOOKUP($I5,'早見表'!$O$3:$P$9,2,TRUE())+IF(AND('入力'!$C$11="有",$I5<=10000000),VLOOKUP('入力'!$E$12,'早見表'!$U$3:$AA$12,IF($I5<=9000000,2,IF($I5<=9500000,3,4)),TRUE()),0)+'入力'!$C$13*'早見表'!$S$5+MAX('入力'!$C$14-'入力'!$C$15,0)*'早見表'!$S$6+IF('入力'!$C$15<=0,0,IF('入力'!$E$16<620001,630000,VLOOKUP('入力'!$E$16,'早見表'!$AD$3:$AF$12,2,TRUE()))*'入力'!$C$15)+'入力'!$C$17*'早見表'!$S$7) | K5: =IF($B5="","",ROUNDDOWN(MAX($I5-$J5,0),-3)) | L5: =IF($B5="","",ROUNDDOWN(MAX($K5*VLOOKUP($K5,'早見表'!$K$3:$M$9,2,TRUE())-VLOOKUP($K5,'早見表'!$K$3:$M$9,3,TRUE()),0),0)) | M5: =IF($B5="","",ROUNDDOWN($L5*0.021,0)) | N5: =IF($B5="","",$L5+$M5) | O5: =IF($B5="","",ROUNDDOWN(MAX($I5-($F5+'早見表'!$S$2+IF(AND('入力'!$C$11="有",$I5<=10000000),VLOOKUP('入力'!$E$12,'早見表'!$U$3:$AA$12,IF($I5<=9000000,5,IF($I5<=9500000,6,7)),TRUE()),0)+'入力'!$C$13*'早見表'!$S$8+MAX('入力'!$C$14-'入力'!$C$15,0)*'早見表'!$S$9+IF('入力'!$C$15<=0,0,IF('入力'!$E$16<620001,450000,VLOOKUP('入力'!$E$16,'早見表'!$AD$3:$AF$12,3,TRUE()))*'入力'!$C$15)+'入力'!$C$17*'早見表'!$S$10),0),-3)*'早見表'!$S$4) | P5: =IF($B5="","",'早見表'!$S$3) | Q5: =IF($B5="","",$O5+$P5) | R5: =IF($B5="","",$F5+$N5+$Q5) | S5: =IF($B5="","",$B5-$R5) | T5: =IF($B5="","",IF($B5=0,"",$S5/$B5)) | U5: =IF($B5="","",$B5+$G5) | V5: =IF($B5="","",'入力'!$C$5-$U5-('結果サマリー'!$C$23-'結果サマリー'!$C$7)) | W5: =IF($B5="","",IF($V5<=0,0,IF($V5<=8000000,$V5*'入力'!$C$65,8000000*'入力'!$C$65+($V5-8000000)*'入力'!$C$66))) | X5: =IF($B5="","",$V5-$W5) | Y5: =IF($B5="","",$X5+$S5+('結果サマリー'!$C$27-'結果サマリー'!$C$6)) | Z5: =IF($B5="","",IF('入力'!$C$5=0,"",1-$Y5/'入力'!$C$5))
A6: 5 | B6: =IF(B5="","",IF(B5+'入力'!$C$71>'入力'!$C$70,"",B5+'入力'!$C$71)) | C6: =IF($B6="","",$B6/12) | D6: =IF($B6="","",IF($B6=0,0,VLOOKUP($C6,'早見表'!$B$3:$D$52,3,TRUE()))) | E6: =IF($B6="","",IF($B6=0,0,VLOOKUP($C6,'早見表'!$G$3:$I$34,3,TRUE()))) | F6: =IF($B6="","",ROUND($D6*('入力'!$C$60+IF('入力'!$C$10="40歳以上64歳以下",'入力'!$C$61,0))/2*12,0)+ROUND($E6*'入力'!$C$62/2*12,0)+ROUND($D6*'入力'!$C$64/2*12,0)) | G6: =IF($B6="","",ROUND($D6*('入力'!$C$60+IF('入力'!$C$10="40歳以上64歳以下",'入力'!$C$61,0))/2*12,0)+ROUND($E6*'入力'!$C$62/2*12,0)+ROUND($E6*'入力'!$C$63*12,0)+ROUND($D6*'入力'!$C$64/2*12,0)) | H6: =IF($B6="","",IF($B6<=2200000,740000,IF($B6<=3600000,$B6*0.3+80000,IF($B6<=6600000,$B6*0.2+440000,IF($B6<=8500000,$B6*0.1+1100000,1950000))))) | I6: =IF($B6="","",MAX($B6-$H6,0)) | J6: =IF($B6="","",$F6+VLOOKUP($I6,'早見表'!$O$3:$P$9,2,TRUE())+IF(AND('入力'!$C$11="有",$I6<=10000000),VLOOKUP('入力'!$E$12,'早見表'!$U$3:$AA$12,IF($I6<=9000000,2,IF($I6<=9500000,3,4)),TRUE()),0)+'入力'!$C$13*'早見表'!$S$5+MAX('入力'!$C$14-'入力'!$C$15,0)*'早見表'!$S$6+IF('入力'!$C$15<=0,0,IF('入力'!$E$16<620001,630000,VLOOKUP('入力'!$E$16,'早見表'!$AD$3:$AF$12,2,TRUE()))*'入力'!$C$15)+'入力'!$C$17*'早見表'!$S$7) | K6: =IF($B6="","",ROUNDDOWN(MAX($I6-$J6,0),-3)) | L6: =IF($B6="","",ROUNDDOWN(MAX($K6*VLOOKUP($K6,'早見表'!$K$3:$M$9,2,TRUE())-VLOOKUP($K6,'早見表'!$K$3:$M$9,3,TRUE()),0),0)) | M6: =IF($B6="","",ROUNDDOWN($L6*0.021,0)) | N6: =IF($B6="","",$L6+$M6) | O6: =IF($B6="","",ROUNDDOWN(MAX($I6-($F6+'早見表'!$S$2+IF(AND('入力'!$C$11="有",$I6<=10000000),VLOOKUP('入力'!$E$12,'早見表'!$U$3:$AA$12,IF($I6<=9000000,5,IF($I6<=9500000,6,7)),TRUE()),0)+'入力'!$C$13*'早見表'!$S$8+MAX('入力'!$C$14-'入力'!$C$15,0)*'早見表'!$S$9+IF('入力'!$C$15<=0,0,IF('入力'!$E$16<620001,450000,VLOOKUP('入力'!$E$16,'早見表'!$AD$3:$AF$12,3,TRUE()))*'入力'!$C$15)+'入力'!$C$17*'早見表'!$S$10),0),-3)*'早見表'!$S$4) | P6: =IF($B6="","",'早見表'!$S$3) | Q6: =IF($B6="","",$O6+$P6) | R6: =IF($B6="","",$F6+$N6+$Q6) | S6: =IF($B6="","",$B6-$R6) | T6: =IF($B6="","",IF($B6=0,"",$S6/$B6)) | U6: =IF($B6="","",$B6+$G6) | V6: =IF($B6="","",'入力'!$C$5-$U6-('結果サマリー'!$C$23-'結果サマリー'!$C$7)) | W6: =IF($B6="","",IF($V6<=0,0,IF($V6<=8000000,$V6*'入力'!$C$65,8000000*'入力'!$C$65+($V6-8000000)*'入力'!$C$66))) | X6: =IF($B6="","",$V6-$W6) | Y6: =IF($B6="","",$X6+$S6+('結果サマリー'!$C$27-'結果サマリー'!$C$6)) | Z6: =IF($B6="","",IF('入力'!$C$5=0,"",1-$Y6/'入力'!$C$5))
A7: 6 | B7: =IF(B6="","",IF(B6+'入力'!$C$71>'入力'!$C$70,"",B6+'入力'!$C$71)) | C7: =IF($B7="","",$B7/12) | D7: =IF($B7="","",IF($B7=0,0,VLOOKUP($C7,'早見表'!$B$3:$D$52,3,TRUE()))) | E7: =IF($B7="","",IF($B7=0,0,VLOOKUP($C7,'早見表'!$G$3:$I$34,3,TRUE()))) | F7: =IF($B7="","",ROUND($D7*('入力'!$C$60+IF('入力'!$C$10="40歳以上64歳以下",'入力'!$C$61,0))/2*12,0)+ROUND($E7*'入力'!$C$62/2*12,0)+ROUND($D7*'入力'!$C$64/2*12,0)) | G7: =IF($B7="","",ROUND($D7*('入力'!$C$60+IF('入力'!$C$10="40歳以上64歳以下",'入力'!$C$61,0))/2*12,0)+ROUND($E7*'入力'!$C$62/2*12,0)+ROUND($E7*'入力'!$C$63*12,0)+ROUND($D7*'入力'!$C$64/2*12,0)) | H7: =IF($B7="","",IF($B7<=2200000,740000,IF($B7<=3600000,$B7*0.3+80000,IF($B7<=6600000,$B7*0.2+440000,IF($B7<=8500000,$B7*0.1+1100000,1950000))))) | I7: =IF($B7="","",MAX($B7-$H7,0)) | J7: =IF($B7="","",$F7+VLOOKUP($I7,'早見表'!$O$3:$P$9,2,TRUE())+IF(AND('入力'!$C$11="有",$I7<=10000000),VLOOKUP('入力'!$E$12,'早見表'!$U$3:$AA$12,IF($I7<=9000000,2,IF($I7<=9500000,3,4)),TRUE()),0)+'入力'!$C$13*'早見表'!$S$5+MAX('入力'!$C$14-'入力'!$C$15,0)*'早見表'!$S$6+IF('入力'!$C$15<=0,0,IF('入力'!$E$16<620001,630000,VLOOKUP('入力'!$E$16,'早見表'!$AD$3:$AF$12,2,TRUE()))*'入力'!$C$15)+'入力'!$C$17*'早見表'!$S$7) | K7: =IF($B7="","",ROUNDDOWN(MAX($I7-$J7,0),-3)) | L7: =IF($B7="","",ROUNDDOWN(MAX($K7*VLOOKUP($K7,'早見表'!$K$3:$M$9,2,TRUE())-VLOOKUP($K7,'早見表'!$K$3:$M$9,3,TRUE()),0),0)) | M7: =IF($B7="","",ROUNDDOWN($L7*0.021,0)) | N7: =IF($B7="","",$L7+$M7) | O7: =IF($B7="","",ROUNDDOWN(MAX($I7-($F7+'早見表'!$S$2+IF(AND('入力'!$C$11="有",$I7<=10000000),VLOOKUP('入力'!$E$12,'早見表'!$U$3:$AA$12,IF($I7<=9000000,5,IF($I7<=9500000,6,7)),TRUE()),0)+'入力'!$C$13*'早見表'!$S$8+MAX('入力'!$C$14-'入力'!$C$15,0)*'早見表'!$S$9+IF('入力'!$C$15<=0,0,IF('入力'!$E$16<620001,450000,VLOOKUP('入力'!$E$16,'早見表'!$AD$3:$AF$12,3,TRUE()))*'入力'!$C$15)+'入力'!$C$17*'早見表'!$S$10),0),-3)*'早見表'!$S$4) | P7: =IF($B7="","",'早見表'!$S$3) | Q7: =IF($B7="","",$O7+$P7) | R7: =IF($B7="","",$F7+$N7+$Q7) | S7: =IF($B7="","",$B7-$R7) | T7: =IF($B7="","",IF($B7=0,"",$S7/$B7)) | U7: =IF($B7="","",$B7+$G7) | V7: =IF($B7="","",'入力'!$C$5-$U7-('結果サマリー'!$C$23-'結果サマリー'!$C$7)) | W7: =IF($B7="","",IF($V7<=0,0,IF($V7<=8000000,$V7*'入力'!$C$65,8000000*'入力'!$C$65+($V7-8000000)*'入力'!$C$66))) | X7: =IF($B7="","",$V7-$W7) | Y7: =IF($B7="","",$X7+$S7+('結果サマリー'!$C$27-'結果サマリー'!$C$6)) | Z7: =IF($B7="","",IF('入力'!$C$5=0,"",1-$Y7/'入力'!$C$5))
A8: 7 | B8: =IF(B7="","",IF(B7+'入力'!$C$71>'入力'!$C$70,"",B7+'入力'!$C$71)) | C8: =IF($B8="","",$B8/12) | D8: =IF($B8="","",IF($B8=0,0,VLOOKUP($C8,'早見表'!$B$3:$D$52,3,TRUE()))) | E8: =IF($B8="","",IF($B8=0,0,VLOOKUP($C8,'早見表'!$G$3:$I$34,3,TRUE()))) | F8: =IF($B8="","",ROUND($D8*('入力'!$C$60+IF('入力'!$C$10="40歳以上64歳以下",'入力'!$C$61,0))/2*12,0)+ROUND($E8*'入力'!$C$62/2*12,0)+ROUND($D8*'入力'!$C$64/2*12,0)) | G8: =IF($B8="","",ROUND($D8*('入力'!$C$60+IF('入力'!$C$10="40歳以上64歳以下",'入力'!$C$61,0))/2*12,0)+ROUND($E8*'入力'!$C$62/2*12,0)+ROUND($E8*'入力'!$C$63*12,0)+ROUND($D8*'入力'!$C$64/2*12,0)) | H8: =IF($B8="","",IF($B8<=2200000,740000,IF($B8<=3600000,$B8*0.3+80000,IF($B8<=6600000,$B8*0.2+440000,IF($B8<=8500000,$B8*0.1+1100000,1950000))))) | I8: =IF($B8="","",MAX($B8-$H8,0)) | J8: =IF($B8="","",$F8+VLOOKUP($I8,'早見表'!$O$3:$P$9,2,TRUE())+IF(AND('入力'!$C$11="有",$I8<=10000000),VLOOKUP('入力'!$E$12,'早見表'!$U$3:$AA$12,IF($I8<=9000000,2,IF($I8<=9500000,3,4)),TRUE()),0)+'入力'!$C$13*'早見表'!$S$5+MAX('入力'!$C$14-'入力'!$C$15,0)*'早見表'!$S$6+IF('入力'!$C$15<=0,0,IF('入力'!$E$16<620001,630000,VLOOKUP('入力'!$E$16,'早見表'!$AD$3:$AF$12,2,TRUE()))*'入力'!$C$15)+'入力'!$C$17*'早見表'!$S$7) | K8: =IF($B8="","",ROUNDDOWN(MAX($I8-$J8,0),-3)) | L8: =IF($B8="","",ROUNDDOWN(MAX($K8*VLOOKUP($K8,'早見表'!$K$3:$M$9,2,TRUE())-VLOOKUP($K8,'早見表'!$K$3:$M$9,3,TRUE()),0),0)) | M8: =IF($B8="","",ROUNDDOWN($L8*0.021,0)) | N8: =IF($B8="","",$L8+$M8) | O8: =IF($B8="","",ROUNDDOWN(MAX($I8-($F8+'早見表'!$S$2+IF(AND('入力'!$C$11="有",$I8<=10000000),VLOOKUP('入力'!$E$12,'早見表'!$U$3:$AA$12,IF($I8<=9000000,5,IF($I8<=9500000,6,7)),TRUE()),0)+'入力'!$C$13*'早見表'!$S$8+MAX('入力'!$C$14-'入力'!$C$15,0)*'早見表'!$S$9+IF('入力'!$C$15<=0,0,IF('入力'!$E$16<620001,450000,VLOOKUP('入力'!$E$16,'早見表'!$AD$3:$AF$12,3,TRUE()))*'入力'!$C$15)+'入力'!$C$17*'早見表'!$S$10),0),-3)*'早見表'!$S$4) | P8: =IF($B8="","",'早見表'!$S$3) | Q8: =IF($B8="","",$O8+$P8) | R8: =IF($B8="","",$F8+$N8+$Q8) | S8: =IF($B8="","",$B8-$R8) | T8: =IF($B8="","",IF($B8=0,"",$S8/$B8)) | U8: =IF($B8="","",$B8+$G8) | V8: =IF($B8="","",'入力'!$C$5-$U8-('結果サマリー'!$C$23-'結果サマリー'!$C$7)) | W8: =IF($B8="","",IF($V8<=0,0,IF($V8<=8000000,$V8*'入力'!$C$65,8000000*'入力'!$C$65+($V8-8000000)*'入力'!$C$66))) | X8: =IF($B8="","",$V8-$W8) | Y8: =IF($B8="","",$X8+$S8+('結果サマリー'!$C$27-'結果サマリー'!$C$6)) | Z8: =IF($B8="","",IF('入力'!$C$5=0,"",1-$Y8/'入力'!$C$5))
A9: 8 | B9: =IF(B8="","",IF(B8+'入力'!$C$71>'入力'!$C$70,"",B8+'入力'!$C$71)) | C9: =IF($B9="","",$B9/12) | D9: =IF($B9="","",IF($B9=0,0,VLOOKUP($C9,'早見表'!$B$3:$D$52,3,TRUE()))) | E9: =IF($B9="","",IF($B9=0,0,VLOOKUP($C9,'早見表'!$G$3:$I$34,3,TRUE()))) | F9: =IF($B9="","",ROUND($D9*('入力'!$C$60+IF('入力'!$C$10="40歳以上64歳以下",'入力'!$C$61,0))/2*12,0)+ROUND($E9*'入力'!$C$62/2*12,0)+ROUND($D9*'入力'!$C$64/2*12,0)) | G9: =IF($B9="","",ROUND($D9*('入力'!$C$60+IF('入力'!$C$10="40歳以上64歳以下",'入力'!$C$61,0))/2*12,0)+ROUND($E9*'入力'!$C$62/2*12,0)+ROUND($E9*'入力'!$C$63*12,0)+ROUND($D9*'入力'!$C$64/2*12,0)) | H9: =IF($B9="","",IF($B9<=2200000,740000,IF($B9<=3600000,$B9*0.3+80000,IF($B9<=6600000,$B9*0.2+440000,IF($B9<=8500000,$B9*0.1+1100000,1950000))))) | I9: =IF($B9="","",MAX($B9-$H9,0)) | J9: =IF($B9="","",$F9+VLOOKUP($I9,'早見表'!$O$3:$P$9,2,TRUE())+IF(AND('入力'!$C$11="有",$I9<=10000000),VLOOKUP('入力'!$E$12,'早見表'!$U$3:$AA$12,IF($I9<=9000000,2,IF($I9<=9500000,3,4)),TRUE()),0)+'入力'!$C$13*'早見表'!$S$5+MAX('入力'!$C$14-'入力'!$C$15,0)*'早見表'!$S$6+IF('入力'!$C$15<=0,0,IF('入力'!$E$16<620001,630000,VLOOKUP('入力'!$E$16,'早見表'!$AD$3:$AF$12,2,TRUE()))*'入力'!$C$15)+'入力'!$C$17*'早見表'!$S$7) | K9: =IF($B9="","",ROUNDDOWN(MAX($I9-$J9,0),-3)) | L9: =IF($B9="","",ROUNDDOWN(MAX($K9*VLOOKUP($K9,'早見表'!$K$3:$M$9,2,TRUE())-VLOOKUP($K9,'早見表'!$K$3:$M$9,3,TRUE()),0),0)) | M9: =IF($B9="","",ROUNDDOWN($L9*0.021,0)) | N9: =IF($B9="","",$L9+$M9) | O9: =IF($B9="","",ROUNDDOWN(MAX($I9-($F9+'早見表'!$S$2+IF(AND('入力'!$C$11="有",$I9<=10000000),VLOOKUP('入力'!$E$12,'早見表'!$U$3:$AA$12,IF($I9<=9000000,5,IF($I9<=9500000,6,7)),TRUE()),0)+'入力'!$C$13*'早見表'!$S$8+MAX('入力'!$C$14-'入力'!$C$15,0)*'早見表'!$S$9+IF('入力'!$C$15<=0,0,IF('入力'!$E$16<620001,450000,VLOOKUP('入力'!$E$16,'早見表'!$AD$3:$AF$12,3,TRUE()))*'入力'!$C$15)+'入力'!$C$17*'早見表'!$S$10),0),-3)*'早見表'!$S$4) | P9: =IF($B9="","",'早見表'!$S$3) | Q9: =IF($B9="","",$O9+$P9) | R9: =IF($B9="","",$F9+$N9+$Q9) | S9: =IF($B9="","",$B9-$R9) | T9: =IF($B9="","",IF($B9=0,"",$S9/$B9)) | U9: =IF($B9="","",$B9+$G9) | V9: =IF($B9="","",'入力'!$C$5-$U9-('結果サマリー'!$C$23-'結果サマリー'!$C$7)) | W9: =IF($B9="","",IF($V9<=0,0,IF($V9<=8000000,$V9*'入力'!$C$65,8000000*'入力'!$C$65+($V9-8000000)*'入力'!$C$66))) | X9: =IF($B9="","",$V9-$W9) | Y9: =IF($B9="","",$X9+$S9+('結果サマリー'!$C$27-'結果サマリー'!$C$6)) | Z9: =IF($B9="","",IF('入力'!$C$5=0,"",1-$Y9/'入力'!$C$5))
A10: 9 | B10: =IF(B9="","",IF(B9+'入力'!$C$71>'入力'!$C$70,"",B9+'入力'!$C$71)) | C10: =IF($B10="","",$B10/12) | D10: =IF($B10="","",IF($B10=0,0,VLOOKUP($C10,'早見表'!$B$3:$D$52,3,TRUE()))) | E10: =IF($B10="","",IF($B10=0,0,VLOOKUP($C10,'早見表'!$G$3:$I$34,3,TRUE()))) | F10: =IF($B10="","",ROUND($D10*('入力'!$C$60+IF('入力'!$C$10="40歳以上64歳以下",'入力'!$C$61,0))/2*12,0)+ROUND($E10*'入力'!$C$62/2*12,0)+ROUND($D10*'入力'!$C$64/2*12,0)) | G10: =IF($B10="","",ROUND($D10*('入力'!$C$60+IF('入力'!$C$10="40歳以上64歳以下",'入力'!$C$61,0))/2*12,0)+ROUND($E10*'入力'!$C$62/2*12,0)+ROUND($E10*'入力'!$C$63*12,0)+ROUND($D10*'入力'!$C$64/2*12,0)) | H10: =IF($B10="","",IF($B10<=2200000,740000,IF($B10<=3600000,$B10*0.3+80000,IF($B10<=6600000,$B10*0.2+440000,IF($B10<=8500000,$B10*0.1+1100000,1950000))))) | I10: =IF($B10="","",MAX($B10-$H10,0)) | J10: =IF($B10="","",$F10+VLOOKUP($I10,'早見表'!$O$3:$P$9,2,TRUE())+IF(AND('入力'!$C$11="有",$I10<=10000000),VLOOKUP('入力'!$E$12,'早見表'!$U$3:$AA$12,IF($I10<=9000000,2,IF($I10<=9500000,3,4)),TRUE()),0)+'入力'!$C$13*'早見表'!$S$5+MAX('入力'!$C$14-'入力'!$C$15,0)*'早見表'!$S$6+IF('入力'!$C$15<=0,0,IF('入力'!$E$16<620001,630000,VLOOKUP('入力'!$E$16,'早見表'!$AD$3:$AF$12,2,TRUE()))*'入力'!$C$15)+'入力'!$C$17*'早見表'!$S$7) | K10: =IF($B10="","",ROUNDDOWN(MAX($I10-$J10,0),-3)) | L10: =IF($B10="","",ROUNDDOWN(MAX($K10*VLOOKUP($K10,'早見表'!$K$3:$M$9,2,TRUE())-VLOOKUP($K10,'早見表'!$K$3:$M$9,3,TRUE()),0),0)) | M10: =IF($B10="","",ROUNDDOWN($L10*0.021,0)) | N10: =IF($B10="","",$L10+$M10) | O10: =IF($B10="","",ROUNDDOWN(MAX($I10-($F10+'早見表'!$S$2+IF(AND('入力'!$C$11="有",$I10<=10000000),VLOOKUP('入力'!$E$12,'早見表'!$U$3:$AA$12,IF($I10<=9000000,5,IF($I10<=9500000,6,7)),TRUE()),0)+'入力'!$C$13*'早見表'!$S$8+MAX('入力'!$C$14-'入力'!$C$15,0)*'早見表'!$S$9+IF('入力'!$C$15<=0,0,IF('入力'!$E$16<620001,450000,VLOOKUP('入力'!$E$16,'早見表'!$AD$3:$AF$12,3,TRUE()))*'入力'!$C$15)+'入力'!$C$17*'早見表'!$S$10),0),-3)*'早見表'!$S$4) | P10: =IF($B10="","",'早見表'!$S$3) | Q10: =IF($B10="","",$O10+$P10) | R10: =IF($B10="","",$F10+$N10+$Q10) | S10: =IF($B10="","",$B10-$R10) | T10: =IF($B10="","",IF($B10=0,"",$S10/$B10)) | U10: =IF($B10="","",$B10+$G10) | V10: =IF($B10="","",'入力'!$C$5-$U10-('結果サマリー'!$C$23-'結果サマリー'!$C$7)) | W10: =IF($B10="","",IF($V10<=0,0,IF($V10<=8000000,$V10*'入力'!$C$65,8000000*'入力'!$C$65+($V10-8000000)*'入力'!$C$66))) | X10: =IF($B10="","",$V10-$W10) | Y10: =IF($B10="","",$X10+$S10+('結果サマリー'!$C$27-'結果サマリー'!$C$6)) | Z10: =IF($B10="","",IF('入力'!$C$5=0,"",1-$Y10/'入力'!$C$5))
A11: 10 | B11: =IF(B10="","",IF(B10+'入力'!$C$71>'入力'!$C$70,"",B10+'入力'!$C$71)) | C11: =IF($B11="","",$B11/12) | D11: =IF($B11="","",IF($B11=0,0,VLOOKUP($C11,'早見表'!$B$3:$D$52,3,TRUE()))) | E11: =IF($B11="","",IF($B11=0,0,VLOOKUP($C11,'早見表'!$G$3:$I$34,3,TRUE()))) | F11: =IF($B11="","",ROUND($D11*('入力'!$C$60+IF('入力'!$C$10="40歳以上64歳以下",'入力'!$C$61,0))/2*12,0)+ROUND($E11*'入力'!$C$62/2*12,0)+ROUND($D11*'入力'!$C$64/2*12,0)) | G11: =IF($B11="","",ROUND($D11*('入力'!$C$60+IF('入力'!$C$10="40歳以上64歳以下",'入力'!$C$61,0))/2*12,0)+ROUND($E11*'入力'!$C$62/2*12,0)+ROUND($E11*'入力'!$C$63*12,0)+ROUND($D11*'入力'!$C$64/2*12,0)) | H11: =IF($B11="","",IF($B11<=2200000,740000,IF($B11<=3600000,$B11*0.3+80000,IF($B11<=6600000,$B11*0.2+440000,IF($B11<=8500000,$B11*0.1+1100000,1950000))))) | I11: =IF($B11="","",MAX($B11-$H11,0)) | J11: =IF($B11="","",$F11+VLOOKUP($I11,'早見表'!$O$3:$P$9,2,TRUE())+IF(AND('入力'!$C$11="有",$I11<=10000000),VLOOKUP('入力'!$E$12,'早見表'!$U$3:$AA$12,IF($I11<=9000000,2,IF($I11<=9500000,3,4)),TRUE()),0)+'入力'!$C$13*'早見表'!$S$5+MAX('入力'!$C$14-'入力'!$C$15,0)*'早見表'!$S$6+IF('入力'!$C$15<=0,0,IF('入力'!$E$16<620001,630000,VLOOKUP('入力'!$E$16,'早見表'!$AD$3:$AF$12,2,TRUE()))*'入力'!$C$15)+'入力'!$C$17*'早見表'!$S$7) | K11: =IF($B11="","",ROUNDDOWN(MAX($I11-$J11,0),-3)) | L11: =IF($B11="","",ROUNDDOWN(MAX($K11*VLOOKUP($K11,'早見表'!$K$3:$M$9,2,TRUE())-VLOOKUP($K11,'早見表'!$K$3:$M$9,3,TRUE()),0),0)) | M11: =IF($B11="","",ROUNDDOWN($L11*0.021,0)) | N11: =IF($B11="","",$L11+$M11) | O11: =IF($B11="","",ROUNDDOWN(MAX($I11-($F11+'早見表'!$S$2+IF(AND('入力'!$C$11="有",$I11<=10000000),VLOOKUP('入力'!$E$12,'早見表'!$U$3:$AA$12,IF($I11<=9000000,5,IF($I11<=9500000,6,7)),TRUE()),0)+'入力'!$C$13*'早見表'!$S$8+MAX('入力'!$C$14-'入力'!$C$15,0)*'早見表'!$S$9+IF('入力'!$C$15<=0,0,IF('入力'!$E$16<620001,450000,VLOOKUP('入力'!$E$16,'早見表'!$AD$3:$AF$12,3,TRUE()))*'入力'!$C$15)+'入力'!$C$17*'早見表'!$S$10),0),-3)*'早見表'!$S$4) | P11: =IF($B11="","",'早見表'!$S$3) | Q11: =IF($B11="","",$O11+$P11) | R11: =IF($B11="","",$F11+$N11+$Q11) | S11: =IF($B11="","",$B11-$R11) | T11: =IF($B11="","",IF($B11=0,"",$S11/$B11)) | U11: =IF($B11="","",$B11+$G11) | V11: =IF($B11="","",'入力'!$C$5-$U11-('結果サマリー'!$C$23-'結果サマリー'!$C$7)) | W11: =IF($B11="","",IF($V11<=0,0,IF($V11<=8000000,$V11*'入力'!$C$65,8000000*'入力'!$C$65+($V11-8000000)*'入力'!$C$66))) | X11: =IF($B11="","",$V11-$W11) | Y11: =IF($B11="","",$X11+$S11+('結果サマリー'!$C$27-'結果サマリー'!$C$6)) | Z11: =IF($B11="","",IF('入力'!$C$5=0,"",1-$Y11/'入力'!$C$5))
A12: 11 | B12: =IF(B11="","",IF(B11+'入力'!$C$71>'入力'!$C$70,"",B11+'入力'!$C$71)) | C12: =IF($B12="","",$B12/12) | D12: =IF($B12="","",IF($B12=0,0,VLOOKUP($C12,'早見表'!$B$3:$D$52,3,TRUE()))) | E12: =IF($B12="","",IF($B12=0,0,VLOOKUP($C12,'早見表'!$G$3:$I$34,3,TRUE()))) | F12: =IF($B12="","",ROUND($D12*('入力'!$C$60+IF('入力'!$C$10="40歳以上64歳以下",'入力'!$C$61,0))/2*12,0)+ROUND($E12*'入力'!$C$62/2*12,0)+ROUND($D12*'入力'!$C$64/2*12,0)) | G12: =IF($B12="","",ROUND($D12*('入力'!$C$60+IF('入力'!$C$10="40歳以上64歳以下",'入力'!$C$61,0))/2*12,0)+ROUND($E12*'入力'!$C$62/2*12,0)+ROUND($E12*'入力'!$C$63*12,0)+ROUND($D12*'入力'!$C$64/2*12,0)) | H12: =IF($B12="","",IF($B12<=2200000,740000,IF($B12<=3600000,$B12*0.3+80000,IF($B12<=6600000,$B12*0.2+440000,IF($B12<=8500000,$B12*0.1+1100000,1950000))))) | I12: =IF($B12="","",MAX($B12-$H12,0)) | J12: =IF($B12="","",$F12+VLOOKUP($I12,'早見表'!$O$3:$P$9,2,TRUE())+IF(AND('入力'!$C$11="有",$I12<=10000000),VLOOKUP('入力'!$E$12,'早見表'!$U$3:$AA$12,IF($I12<=9000000,2,IF($I12<=9500000,3,4)),TRUE()),0)+'入力'!$C$13*'早見表'!$S$5+MAX('入力'!$C$14-'入力'!$C$15,0)*'早見表'!$S$6+IF('入力'!$C$15<=0,0,IF('入力'!$E$16<620001,630000,VLOOKUP('入力'!$E$16,'早見表'!$AD$3:$AF$12,2,TRUE()))*'入力'!$C$15)+'入力'!$C$17*'早見表'!$S$7) | K12: =IF($B12="","",ROUNDDOWN(MAX($I12-$J12,0),-3)) | L12: =IF($B12="","",ROUNDDOWN(MAX($K12*VLOOKUP($K12,'早見表'!$K$3:$M$9,2,TRUE())-VLOOKUP($K12,'早見表'!$K$3:$M$9,3,TRUE()),0),0)) | M12: =IF($B12="","",ROUNDDOWN($L12*0.021,0)) | N12: =IF($B12="","",$L12+$M12) | O12: =IF($B12="","",ROUNDDOWN(MAX($I12-($F12+'早見表'!$S$2+IF(AND('入力'!$C$11="有",$I12<=10000000),VLOOKUP('入力'!$E$12,'早見表'!$U$3:$AA$12,IF($I12<=9000000,5,IF($I12<=9500000,6,7)),TRUE()),0)+'入力'!$C$13*'早見表'!$S$8+MAX('入力'!$C$14-'入力'!$C$15,0)*'早見表'!$S$9+IF('入力'!$C$15<=0,0,IF('入力'!$E$16<620001,450000,VLOOKUP('入力'!$E$16,'早見表'!$AD$3:$AF$12,3,TRUE()))*'入力'!$C$15)+'入力'!$C$17*'早見表'!$S$10),0),-3)*'早見表'!$S$4) | P12: =IF($B12="","",'早見表'!$S$3) | Q12: =IF($B12="","",$O12+$P12) | R12: =IF($B12="","",$F12+$N12+$Q12) | S12: =IF($B12="","",$B12-$R12) | T12: =IF($B12="","",IF($B12=0,"",$S12/$B12)) | U12: =IF($B12="","",$B12+$G12) | V12: =IF($B12="","",'入力'!$C$5-$U12-('結果サマリー'!$C$23-'結果サマリー'!$C$7)) | W12: =IF($B12="","",IF($V12<=0,0,IF($V12<=8000000,$V12*'入力'!$C$65,8000000*'入力'!$C$65+($V12-8000000)*'入力'!$C$66))) | X12: =IF($B12="","",$V12-$W12) | Y12: =IF($B12="","",$X12+$S12+('結果サマリー'!$C$27-'結果サマリー'!$C$6)) | Z12: =IF($B12="","",IF('入力'!$C$5=0,"",1-$Y12/'入力'!$C$5))
A13: 12 | B13: =IF(B12="","",IF(B12+'入力'!$C$71>'入力'!$C$70,"",B12+'入力'!$C$71)) | C13: =IF($B13="","",$B13/12) | D13: =IF($B13="","",IF($B13=0,0,VLOOKUP($C13,'早見表'!$B$3:$D$52,3,TRUE()))) | E13: =IF($B13="","",IF($B13=0,0,VLOOKUP($C13,'早見表'!$G$3:$I$34,3,TRUE()))) | F13: =IF($B13="","",ROUND($D13*('入力'!$C$60+IF('入力'!$C$10="40歳以上64歳以下",'入力'!$C$61,0))/2*12,0)+ROUND($E13*'入力'!$C$62/2*12,0)+ROUND($D13*'入力'!$C$64/2*12,0)) | G13: =IF($B13="","",ROUND($D13*('入力'!$C$60+IF('入力'!$C$10="40歳以上64歳以下",'入力'!$C$61,0))/2*12,0)+ROUND($E13*'入力'!$C$62/2*12,0)+ROUND($E13*'入力'!$C$63*12,0)+ROUND($D13*'入力'!$C$64/2*12,0)) | H13: =IF($B13="","",IF($B13<=2200000,740000,IF($B13<=3600000,$B13*0.3+80000,IF($B13<=6600000,$B13*0.2+440000,IF($B13<=8500000,$B13*0.1+1100000,1950000))))) | I13: =IF($B13="","",MAX($B13-$H13,0)) | J13: =IF($B13="","",$F13+VLOOKUP($I13,'早見表'!$O$3:$P$9,2,TRUE())+IF(AND('入力'!$C$11="有",$I13<=10000000),VLOOKUP('入力'!$E$12,'早見表'!$U$3:$AA$12,IF($I13<=9000000,2,IF($I13<=9500000,3,4)),TRUE()),0)+'入力'!$C$13*'早見表'!$S$5+MAX('入力'!$C$14-'入力'!$C$15,0)*'早見表'!$S$6+IF('入力'!$C$15<=0,0,IF('入力'!$E$16<620001,630000,VLOOKUP('入力'!$E$16,'早見表'!$AD$3:$AF$12,2,TRUE()))*'入力'!$C$15)+'入力'!$C$17*'早見表'!$S$7) | K13: =IF($B13="","",ROUNDDOWN(MAX($I13-$J13,0),-3)) | L13: =IF($B13="","",ROUNDDOWN(MAX($K13*VLOOKUP($K13,'早見表'!$K$3:$M$9,2,TRUE())-VLOOKUP($K13,'早見表'!$K$3:$M$9,3,TRUE()),0),0)) | M13: =IF($B13="","",ROUNDDOWN($L13*0.021,0)) | N13: =IF($B13="","",$L13+$M13) | O13: =IF($B13="","",ROUNDDOWN(MAX($I13-($F13+'早見表'!$S$2+IF(AND('入力'!$C$11="有",$I13<=10000000),VLOOKUP('入力'!$E$12,'早見表'!$U$3:$AA$12,IF($I13<=9000000,5,IF($I13<=9500000,6,7)),TRUE()),0)+'入力'!$C$13*'早見表'!$S$8+MAX('入力'!$C$14-'入力'!$C$15,0)*'早見表'!$S$9+IF('入力'!$C$15<=0,0,IF('入力'!$E$16<620001,450000,VLOOKUP('入力'!$E$16,'早見表'!$AD$3:$AF$12,3,TRUE()))*'入力'!$C$15)+'入力'!$C$17*'早見表'!$S$10),0),-3)*'早見表'!$S$4) | P13: =IF($B13="","",'早見表'!$S$3) | Q13: =IF($B13="","",$O13+$P13) | R13: =IF($B13="","",$F13+$N13+$Q13) | S13: =IF($B13="","",$B13-$R13) | T13: =IF($B13="","",IF($B13=0,"",$S13/$B13)) | U13: =IF($B13="","",$B13+$G13) | V13: =IF($B13="","",'入力'!$C$5-$U13-('結果サマリー'!$C$23-'結果サマリー'!$C$7)) | W13: =IF($B13="","",IF($V13<=0,0,IF($V13<=8000000,$V13*'入力'!$C$65,8000000*'入力'!$C$65+($V13-8000000)*'入力'!$C$66))) | X13: =IF($B13="","",$V13-$W13) | Y13: =IF($B13="","",$X13+$S13+('結果サマリー'!$C$27-'結果サマリー'!$C$6)) | Z13: =IF($B13="","",IF('入力'!$C$5=0,"",1-$Y13/'入力'!$C$5))
A14: 13 | B14: =IF(B13="","",IF(B13+'入力'!$C$71>'入力'!$C$70,"",B13+'入力'!$C$71)) | C14: =IF($B14="","",$B14/12) | D14: =IF($B14="","",IF($B14=0,0,VLOOKUP($C14,'早見表'!$B$3:$D$52,3,TRUE()))) | E14: =IF($B14="","",IF($B14=0,0,VLOOKUP($C14,'早見表'!$G$3:$I$34,3,TRUE()))) | F14: =IF($B14="","",ROUND($D14*('入力'!$C$60+IF('入力'!$C$10="40歳以上64歳以下",'入力'!$C$61,0))/2*12,0)+ROUND($E14*'入力'!$C$62/2*12,0)+ROUND($D14*'入力'!$C$64/2*12,0)) | G14: =IF($B14="","",ROUND($D14*('入力'!$C$60+IF('入力'!$C$10="40歳以上64歳以下",'入力'!$C$61,0))/2*12,0)+ROUND($E14*'入力'!$C$62/2*12,0)+ROUND($E14*'入力'!$C$63*12,0)+ROUND($D14*'入力'!$C$64/2*12,0)) | H14: =IF($B14="","",IF($B14<=2200000,740000,IF($B14<=3600000,$B14*0.3+80000,IF($B14<=6600000,$B14*0.2+440000,IF($B14<=8500000,$B14*0.1+1100000,1950000))))) | I14: =IF($B14="","",MAX($B14-$H14,0)) | J14: =IF($B14="","",$F14+VLOOKUP($I14,'早見表'!$O$3:$P$9,2,TRUE())+IF(AND('入力'!$C$11="有",$I14<=10000000),VLOOKUP('入力'!$E$12,'早見表'!$U$3:$AA$12,IF($I14<=9000000,2,IF($I14<=9500000,3,4)),TRUE()),0)+'入力'!$C$13*'早見表'!$S$5+MAX('入力'!$C$14-'入力'!$C$15,0)*'早見表'!$S$6+IF('入力'!$C$15<=0,0,IF('入力'!$E$16<620001,630000,VLOOKUP('入力'!$E$16,'早見表'!$AD$3:$AF$12,2,TRUE()))*'入力'!$C$15)+'入力'!$C$17*'早見表'!$S$7) | K14: =IF($B14="","",ROUNDDOWN(MAX($I14-$J14,0),-3)) | L14: =IF($B14="","",ROUNDDOWN(MAX($K14*VLOOKUP($K14,'早見表'!$K$3:$M$9,2,TRUE())-VLOOKUP($K14,'早見表'!$K$3:$M$9,3,TRUE()),0),0)) | M14: =IF($B14="","",ROUNDDOWN($L14*0.021,0)) | N14: =IF($B14="","",$L14+$M14) | O14: =IF($B14="","",ROUNDDOWN(MAX($I14-($F14+'早見表'!$S$2+IF(AND('入力'!$C$11="有",$I14<=10000000),VLOOKUP('入力'!$E$12,'早見表'!$U$3:$AA$12,IF($I14<=9000000,5,IF($I14<=9500000,6,7)),TRUE()),0)+'入力'!$C$13*'早見表'!$S$8+MAX('入力'!$C$14-'入力'!$C$15,0)*'早見表'!$S$9+IF('入力'!$C$15<=0,0,IF('入力'!$E$16<620001,450000,VLOOKUP('入力'!$E$16,'早見表'!$AD$3:$AF$12,3,TRUE()))*'入力'!$C$15)+'入力'!$C$17*'早見表'!$S$10),0),-3)*'早見表'!$S$4) | P14: =IF($B14="","",'早見表'!$S$3) | Q14: =IF($B14="","",$O14+$P14) | R14: =IF($B14="","",$F14+$N14+$Q14) | S14: =IF($B14="","",$B14-$R14) | T14: =IF($B14="","",IF($B14=0,"",$S14/$B14)) | U14: =IF($B14="","",$B14+$G14) | V14: =IF($B14="","",'入力'!$C$5-$U14-('結果サマリー'!$C$23-'結果サマリー'!$C$7)) | W14: =IF($B14="","",IF($V14<=0,0,IF($V14<=8000000,$V14*'入力'!$C$65,8000000*'入力'!$C$65+($V14-8000000)*'入力'!$C$66))) | X14: =IF($B14="","",$V14-$W14) | Y14: =IF($B14="","",$X14+$S14+('結果サマリー'!$C$27-'結果サマリー'!$C$6)) | Z14: =IF($B14="","",IF('入力'!$C$5=0,"",1-$Y14/'入力'!$C$5))
... A301: 300 | B301: =IF(B300="","",IF(B300+'入力'!$C$71>'入力'!$C$70,"",B300+'入力'!$C$71)) | C301: =IF($B301="","",$B301/12) | D301: =IF($B301="","",IF($B301=0,0,VLOOKUP($C301,'早見表'!$B$3:$D$52,3,TRUE()))) | E301: =IF($B301="","",IF($B301=0,0,VLOOKUP($C301,'早見表'!$G$3:$I$34,3,TRUE()))) | F301: =IF($B301="","",ROUND($D301*('入力'!$C$60+IF('入力'!$C$10="40歳以上64歳以下",'入力'!$C$61,0))/2*12,0)+ROUND($E301*'入力'!$C$62/2*12,0)+ROUND($D301*'入力'!$C$64/2*12,0)) | G301: =IF($B301="","",ROUND($D301*('入力'!$C$60+IF('入力'!$C$10="40歳以上64歳以下",'入力'!$C$61,0))/2*12,0)+ROUND($E301*'入力'!$C$62/2*12,0)+ROUND($E301*'入力'!$C$63*12,0)+ROUND($D301*'入力'!$C$64/2*12,0)) | H301: =IF($B301="","",IF($B301<=2200000,740000,IF($B301<=3600000,$B301*0.3+80000,IF($B301<=6600000,$B301*0.2+440000,IF($B301<=8500000,$B301*0.1+1100000,1950000))))) | I301: =IF($B301="","",MAX($B301-$H301,0)) | J301: =IF($B301="","",$F301+VLOOKUP($I301,'早見表'!$O$3:$P$9,2,TRUE())+IF(AND('入力'!$C$11="有",$I301<=10000000),VLOOKUP('入力'!$E$12,'早見表'!$U$3:$AA$12,IF($I301<=9000000,2,IF($I301<=9500000,3,4)),TRUE()),0)+'入力'!$C$13*'早見表'!$S$5+MAX('入力'!$C$14-'入力'!$C$15,0)*'早見表'!$S$6+IF('入力'!$C$15<=0,0,IF('入力'!$E$16<620001,630000,VLOOKUP('入力'!$E$16,'早見表'!$AD$3:$AF$12,2,TRUE()))*'入力'!$C$15)+'入力'!$C$17*'早見表'!$S$7) | K301: =IF($B301="","",ROUNDDOWN(MAX($I301-$J301,0),-3)) | L301: =IF($B301="","",ROUNDDOWN(MAX($K301*VLOOKUP($K301,'早見表'!$K$3:$M$9,2,TRUE())-VLOOKUP($K301,'早見表'!$K$3:$M$9,3,TRUE()),0),0)) | M301: =IF($B301="","",ROUNDDOWN($L301*0.021,0)) | N301: =IF($B301="","",$L301+$M301) | O301: =IF($B301="","",ROUNDDOWN(MAX($I301-($F301+'早見表'!$S$2+IF(AND('入力'!$C$11="有",$I301<=10000000),VLOOKUP('入力'!$E$12,'早見表'!$U$3:$AA$12,IF($I301<=9000000,5,IF($I301<=9500000,6,7)),TRUE()),0)+'入力'!$C$13*'早見表'!$S$8+MAX('入力'!$C$14-'入力'!$C$15,0)*'早見表'!$S$9+IF('入力'!$C$15<=0,0,IF('入力'!$E$16<620001,450000,VLOOKUP('入力'!$E$16,'早見表'!$AD$3:$AF$12,3,TRUE()))*'入力'!$C$15)+'入力'!$C$17*'早見表'!$S$10),0),-3)*'早見表'!$S$4) | P301: =IF($B301="","",'早見表'!$S$3) | Q301: =IF($B301="","",$O301+$P301) | R301: =IF($B301="","",$F301+$N301+$Q301) | S301: =IF($B301="","",$B301-$R301) | T301: =IF($B301="","",IF($B301=0,"",$S301/$B301)) | U301: =IF($B301="","",$B301+$G301) | V301: =IF($B301="","",'入力'!$C$5-$U301-('結果サマリー'!$C$23-'結果サマリー'!$C$7)) | W301: =IF($B301="","",IF($V301<=0,0,IF($V301<=8000000,$V301*'入力'!$C$65,8000000*'入力'!$C$65+($V301-8000000)*'入力'!$C$66))) | X301: =IF($B301="","",$V301-$W301) | Y301: =IF($B301="","",$X301+$S301+('結果サマリー'!$C$27-'結果サマリー'!$C$6)) | Z301: =IF($B301="","",IF('入力'!$C$5=0,"",1-$Y301/'入力'!$C$5))

Sheet シミュレーション2
A1: # | B1: 役員報酬(年額) | C1: 役員報酬(月額) | D1: 標準報酬月額(健保) | E1: 標準報酬月額(厚年) | F1: 社会保険料(個人負担) | G1: 社会保険料(会社負担) | H1: 給与所得控除 | I1: 給与所得 | J1: 所得控除合計(所得税) | K1: 課税所得(所得税) | L1: 所得税 | M1: 復興特別所得税 | N1: 所得税等合計 | O1: 住民税(所得割) | P1: 住民税(均等割等) | Q1: 住民税合計 | R1: 個人負担合計 | S1: 個人手取り額 | T1: 個人手取り率 | U1: 会社コスト(この役員の報酬+法定福利費) | V1: 役員報酬控除後利益(全役員ベース) | W1: 法人税等 | X1: 内部留保(税引後) | Y1: トータル手取り(内部留保+個人手取り合計) | Z1: 実効負担率(対税引前利益)
A2: 1 | B2: ='入力'!$C$69 | C2: =IF($B2="","",$B2/12) | D2: =IF($B2="","",IF($B2=0,0,VLOOKUP($C2,'早見表'!$B$3:$D$52,3,TRUE()))) | E2: =IF($B2="","",IF($B2=0,0,VLOOKUP($C2,'早見表'!$G$3:$I$34,3,TRUE()))) | F2: =IF($B2="","",ROUND($D2*('入力'!$C$60+IF('入力'!$C$20="40歳以上64歳以下",'入力'!$C$61,0))/2*12,0)+ROUND($E2*'入力'!$C$62/2*12,0)+ROUND($D2*'入力'!$C$64/2*12,0)) | G2: =IF($B2="","",ROUND($D2*('入力'!$C$60+IF('入力'!$C$20="40歳以上64歳以下",'入力'!$C$61,0))/2*12,0)+ROUND($E2*'入力'!$C$62/2*12,0)+ROUND($E2*'入力'!$C$63*12,0)+ROUND($D2*'入力'!$C$64/2*12,0)) | H2: =IF($B2="","",IF($B2<=2200000,740000,IF($B2<=3600000,$B2*0.3+80000,IF($B2<=6600000,$B2*0.2+440000,IF($B2<=8500000,$B2*0.1+1100000,1950000))))) | I2: =IF($B2="","",MAX($B2-$H2,0)) | J2: =IF($B2="","",$F2+VLOOKUP($I2,'早見表'!$O$3:$P$9,2,TRUE())+IF(AND('入力'!$C$21="有",$I2<=10000000),VLOOKUP('入力'!$E$22,'早見表'!$U$3:$AA$12,IF($I2<=9000000,2,IF($I2<=9500000,3,4)),TRUE()),0)+'入力'!$C$23*'早見表'!$S$5+MAX('入力'!$C$24-'入力'!$C$25,0)*'早見表'!$S$6+IF('入力'!$C$25<=0,0,IF('入力'!$E$26<620001,630000,VLOOKUP('入力'!$E$26,'早見表'!$AD$3:$AF$12,2,TRUE()))*'入力'!$C$25)+'入力'!$C$27*'早見表'!$S$7) | K2: =IF($B2="","",ROUNDDOWN(MAX($I2-$J2,0),-3)) | L2: =IF($B2="","",ROUNDDOWN(MAX($K2*VLOOKUP($K2,'早見表'!$K$3:$M$9,2,TRUE())-VLOOKUP($K2,'早見表'!$K$3:$M$9,3,TRUE()),0),0)) | M2: =IF($B2="","",ROUNDDOWN($L2*0.021,0)) | N2: =IF($B2="","",$L2+$M2) | O2: =IF($B2="","",ROUNDDOWN(MAX($I2-($F2+'早見表'!$S$2+IF(AND('入力'!$C$21="有",$I2<=10000000),VLOOKUP('入力'!$E$22,'早見表'!$U$3:$AA$12,IF($I2<=9000000,5,IF($I2<=9500000,6,7)),TRUE()),0)+'入力'!$C$23*'早見表'!$S$8+MAX('入力'!$C$24-'入力'!$C$25,0)*'早見表'!$S$9+IF('入力'!$C$25<=0,0,IF('入力'!$E$26<620001,450000,VLOOKUP('入力'!$E$26,'早見表'!$AD$3:$AF$12,3,TRUE()))*'入力'!$C$25)+'入力'!$C$27*'早見表'!$S$10),0),-3)*'早見表'!$S$4) | P2: =IF($B2="","",'早見表'!$S$3) | Q2: =IF($B2="","",$O2+$P2) | R2: =IF($B2="","",$F2+$N2+$Q2) | S2: =IF($B2="","",$B2-$R2) | T2: =IF($B2="","",IF($B2=0,"",$S2/$B2)) | U2: =IF($B2="","",$B2+$G2) | V2: =IF($B2="","",'入力'!$C$5-$U2-('結果サマリー'!$C$23-'結果サマリー'!$C$10)) | W2: =IF($B2="","",IF($V2<=0,0,IF($V2<=8000000,$V2*'入力'!$C$65,8000000*'入力'!$C$65+($V2-8000000)*'入力'!$C$66))) | X2: =IF($B2="","",$V2-$W2) | Y2: =IF($B2="","",$X2+$S2+('結果サマリー'!$C$27-'結果サマリー'!$C$9)) | Z2: =IF($B2="","",IF('入力'!$C$5=0,"",1-$Y2/'入力'!$C$5))
A3: 2 | B3: =IF(B2="","",IF(B2+'入力'!$C$71>'入力'!$C$70,"",B2+'入力'!$C$71)) | C3: =IF($B3="","",$B3/12) | D3: =IF($B3="","",IF($B3=0,0,VLOOKUP($C3,'早見表'!$B$3:$D$52,3,TRUE()))) | E3: =IF($B3="","",IF($B3=0,0,VLOOKUP($C3,'早見表'!$G$3:$I$34,3,TRUE()))) | F3: =IF($B3="","",ROUND($D3*('入力'!$C$60+IF('入力'!$C$20="40歳以上64歳以下",'入力'!$C$61,0))/2*12,0)+ROUND($E3*'入力'!$C$62/2*12,0)+ROUND($D3*'入力'!$C$64/2*12,0)) | G3: =IF($B3="","",ROUND($D3*('入力'!$C$60+IF('入力'!$C$20="40歳以上64歳以下",'入力'!$C$61,0))/2*12,0)+ROUND($E3*'入力'!$C$62/2*12,0)+ROUND($E3*'入力'!$C$63*12,0)+ROUND($D3*'入力'!$C$64/2*12,0)) | H3: =IF($B3="","",IF($B3<=2200000,740000,IF($B3<=3600000,$B3*0.3+80000,IF($B3<=6600000,$B3*0.2+440000,IF($B3<=8500000,$B3*0.1+1100000,1950000))))) | I3: =IF($B3="","",MAX($B3-$H3,0)) | J3: =IF($B3="","",$F3+VLOOKUP($I3,'早見表'!$O$3:$P$9,2,TRUE())+IF(AND('入力'!$C$21="有",$I3<=10000000),VLOOKUP('入力'!$E$22,'早見表'!$U$3:$AA$12,IF($I3<=9000000,2,IF($I3<=9500000,3,4)),TRUE()),0)+'入力'!$C$23*'早見表'!$S$5+MAX('入力'!$C$24-'入力'!$C$25,0)*'早見表'!$S$6+IF('入力'!$C$25<=0,0,IF('入力'!$E$26<620001,630000,VLOOKUP('入力'!$E$26,'早見表'!$AD$3:$AF$12,2,TRUE()))*'入力'!$C$25)+'入力'!$C$27*'早見表'!$S$7) | K3: =IF($B3="","",ROUNDDOWN(MAX($I3-$J3,0),-3)) | L3: =IF($B3="","",ROUNDDOWN(MAX($K3*VLOOKUP($K3,'早見表'!$K$3:$M$9,2,TRUE())-VLOOKUP($K3,'早見表'!$K$3:$M$9,3,TRUE()),0),0)) | M3: =IF($B3="","",ROUNDDOWN($L3*0.021,0)) | N3: =IF($B3="","",$L3+$M3) | O3: =IF($B3="","",ROUNDDOWN(MAX($I3-($F3+'早見表'!$S$2+IF(AND('入力'!$C$21="有",$I3<=10000000),VLOOKUP('入力'!$E$22,'早見表'!$U$3:$AA$12,IF($I3<=9000000,5,IF($I3<=9500000,6,7)),TRUE()),0)+'入力'!$C$23*'早見表'!$S$8+MAX('入力'!$C$24-'入力'!$C$25,0)*'早見表'!$S$9+IF('入力'!$C$25<=0,0,IF('入力'!$E$26<620001,450000,VLOOKUP('入力'!$E$26,'早見表'!$AD$3:$AF$12,3,TRUE()))*'入力'!$C$25)+'入力'!$C$27*'早見表'!$S$10),0),-3)*'早見表'!$S$4) | P3: =IF($B3="","",'早見表'!$S$3) | Q3: =IF($B3="","",$O3+$P3) | R3: =IF($B3="","",$F3+$N3+$Q3) | S3: =IF($B3="","",$B3-$R3) | T3: =IF($B3="","",IF($B3=0,"",$S3/$B3)) | U3: =IF($B3="","",$B3+$G3) | V3: =IF($B3="","",'入力'!$C$5-$U3-('結果サマリー'!$C$23-'結果サマリー'!$C$10)) | W3: =IF($B3="","",IF($V3<=0,0,IF($V3<=8000000,$V3*'入力'!$C$65,8000000*'入力'!$C$65+($V3-8000000)*'入力'!$C$66))) | X3: =IF($B3="","",$V3-$W3) | Y3: =IF($B3="","",$X3+$S3+('結果サマリー'!$C$27-'結果サマリー'!$C$9)) | Z3: =IF($B3="","",IF('入力'!$C$5=0,"",1-$Y3/'入力'!$C$5))
A4: 3 | B4: =IF(B3="","",IF(B3+'入力'!$C$71>'入力'!$C$70,"",B3+'入力'!$C$71)) | C4: =IF($B4="","",$B4/12) | D4: =IF($B4="","",IF($B4=0,0,VLOOKUP($C4,'早見表'!$B$3:$D$52,3,TRUE()))) | E4: =IF($B4="","",IF($B4=0,0,VLOOKUP($C4,'早見表'!$G$3:$I$34,3,TRUE()))) | F4: =IF($B4="","",ROUND($D4*('入力'!$C$60+IF('入力'!$C$20="40歳以上64歳以下",'入力'!$C$61,0))/2*12,0)+ROUND($E4*'入力'!$C$62/2*12,0)+ROUND($D4*'入力'!$C$64/2*12,0)) | G4: =IF($B4="","",ROUND($D4*('入力'!$C$60+IF('入力'!$C$20="40歳以上64歳以下",'入力'!$C$61,0))/2*12,0)+ROUND($E4*'入力'!$C$62/2*12,0)+ROUND($E4*'入力'!$C$63*12,0)+ROUND($D4*'入力'!$C$64/2*12,0)) | H4: =IF($B4="","",IF($B4<=2200000,740000,IF($B4<=3600000,$B4*0.3+80000,IF($B4<=6600000,$B4*0.2+440000,IF($B4<=8500000,$B4*0.1+1100000,1950000))))) | I4: =IF($B4="","",MAX($B4-$H4,0)) | J4: =IF($B4="","",$F4+VLOOKUP($I4,'早見表'!$O$3:$P$9,2,TRUE())+IF(AND('入力'!$C$21="有",$I4<=10000000),VLOOKUP('入力'!$E$22,'早見表'!$U$3:$AA$12,IF($I4<=9000000,2,IF($I4<=9500000,3,4)),TRUE()),0)+'入力'!$C$23*'早見表'!$S$5+MAX('入力'!$C$24-'入力'!$C$25,0)*'早見表'!$S$6+IF('入力'!$C$25<=0,0,IF('入力'!$E$26<620001,630000,VLOOKUP('入力'!$E$26,'早見表'!$AD$3:$AF$12,2,TRUE()))*'入力'!$C$25)+'入力'!$C$27*'早見表'!$S$7) | K4: =IF($B4="","",ROUNDDOWN(MAX($I4-$J4,0),-3)) | L4: =IF($B4="","",ROUNDDOWN(MAX($K4*VLOOKUP($K4,'早見表'!$K$3:$M$9,2,TRUE())-VLOOKUP($K4,'早見表'!$K$3:$M$9,3,TRUE()),0),0)) | M4: =IF($B4="","",ROUNDDOWN($L4*0.021,0)) | N4: =IF($B4="","",$L4+$M4) | O4: =IF($B4="","",ROUNDDOWN(MAX($I4-($F4+'早見表'!$S$2+IF(AND('入力'!$C$21="有",$I4<=10000000),VLOOKUP('入力'!$E$22,'早見表'!$U$3:$AA$12,IF($I4<=9000000,5,IF($I4<=9500000,6,7)),TRUE()),0)+'入力'!$C$23*'早見表'!$S$8+MAX('入力'!$C$24-'入力'!$C$25,0)*'早見表'!$S$9+IF('入力'!$C$25<=0,0,IF('入力'!$E$26<620001,450000,VLOOKUP('入力'!$E$26,'早見表'!$AD$3:$AF$12,3,TRUE()))*'入力'!$C$25)+'入力'!$C$27*'早見表'!$S$10),0),-3)*'早見表'!$S$4) | P4: =IF($B4="","",'早見表'!$S$3) | Q4: =IF($B4="","",$O4+$P4) | R4: =IF($B4="","",$F4+$N4+$Q4) | S4: =IF($B4="","",$B4-$R4) | T4: =IF($B4="","",IF($B4=0,"",$S4/$B4)) | U4: =IF($B4="","",$B4+$G4) | V4: =IF($B4="","",'入力'!$C$5-$U4-('結果サマリー'!$C$23-'結果サマリー'!$C$10)) | W4: =IF($B4="","",IF($V4<=0,0,IF($V4<=8000000,$V4*'入力'!$C$65,8000000*'入力'!$C$65+($V4-8000000)*'入力'!$C$66))) | X4: =IF($B4="","",$V4-$W4) | Y4: =IF($B4="","",$X4+$S4+('結果サマリー'!$C$27-'結果サマリー'!$C$9)) | Z4: =IF($B4="","",IF('入力'!$C$5=0,"",1-$Y4/'入力'!$C$5))
A5: 4 | B5: =IF(B4="","",IF(B4+'入力'!$C$71>'入力'!$C$70,"",B4+'入力'!$C$71)) | C5: =IF($B5="","",$B5/12) | D5: =IF($B5="","",IF($B5=0,0,VLOOKUP($C5,'早見表'!$B$3:$D$52,3,TRUE()))) | E5: =IF($B5="","",IF($B5=0,0,VLOOKUP($C5,'早見表'!$G$3:$I$34,3,TRUE()))) | F5: =IF($B5="","",ROUND($D5*('入力'!$C$60+IF('入力'!$C$20="40歳以上64歳以下",'入力'!$C$61,0))/2*12,0)+ROUND($E5*'入力'!$C$62/2*12,0)+ROUND($D5*'入力'!$C$64/2*12,0)) | G5: =IF($B5="","",ROUND($D5*('入力'!$C$60+IF('入力'!$C$20="40歳以上64歳以下",'入力'!$C$61,0))/2*12,0)+ROUND($E5*'入力'!$C$62/2*12,0)+ROUND($E5*'入力'!$C$63*12,0)+ROUND($D5*'入力'!$C$64/2*12,0)) | H5: =IF($B5="","",IF($B5<=2200000,740000,IF($B5<=3600000,$B5*0.3+80000,IF($B5<=6600000,$B5*0.2+440000,IF($B5<=8500000,$B5*0.1+1100000,1950000))))) | I5: =IF($B5="","",MAX($B5-$H5,0)) | J5: =IF($B5="","",$F5+VLOOKUP($I5,'早見表'!$O$3:$P$9,2,TRUE())+IF(AND('入力'!$C$21="有",$I5<=10000000),VLOOKUP('入力'!$E$22,'早見表'!$U$3:$AA$12,IF($I5<=9000000,2,IF($I5<=9500000,3,4)),TRUE()),0)+'入力'!$C$23*'早見表'!$S$5+MAX('入力'!$C$24-'入力'!$C$25,0)*'早見表'!$S$6+IF('入力'!$C$25<=0,0,IF('入力'!$E$26<620001,630000,VLOOKUP('入力'!$E$26,'早見表'!$AD$3:$AF$12,2,TRUE()))*'入力'!$C$25)+'入力'!$C$27*'早見表'!$S$7) | K5: =IF($B5="","",ROUNDDOWN(MAX($I5-$J5,0),-3)) | L5: =IF($B5="","",ROUNDDOWN(MAX($K5*VLOOKUP($K5,'早見表'!$K$3:$M$9,2,TRUE())-VLOOKUP($K5,'早見表'!$K$3:$M$9,3,TRUE()),0),0)) | M5: =IF($B5="","",ROUNDDOWN($L5*0.021,0)) | N5: =IF($B5="","",$L5+$M5) | O5: =IF($B5="","",ROUNDDOWN(MAX($I5-($F5+'早見表'!$S$2+IF(AND('入力'!$C$21="有",$I5<=10000000),VLOOKUP('入力'!$E$22,'早見表'!$U$3:$AA$12,IF($I5<=9000000,5,IF($I5<=9500000,6,7)),TRUE()),0)+'入力'!$C$23*'早見表'!$S$8+MAX('入力'!$C$24-'入力'!$C$25,0)*'早見表'!$S$9+IF('入力'!$C$25<=0,0,IF('入力'!$E$26<620001,450000,VLOOKUP('入力'!$E$26,'早見表'!$AD$3:$AF$12,3,TRUE()))*'入力'!$C$25)+'入力'!$C$27*'早見表'!$S$10),0),-3)*'早見表'!$S$4) | P5: =IF($B5="","",'早見表'!$S$3) | Q5: =IF($B5="","",$O5+$P5) | R5: =IF($B5="","",$F5+$N5+$Q5) | S5: =IF($B5="","",$B5-$R5) | T5: =IF($B5="","",IF($B5=0,"",$S5/$B5)) | U5: =IF($B5="","",$B5+$G5) | V5: =IF($B5="","",'入力'!$C$5-$U5-('結果サマリー'!$C$23-'結果サマリー'!$C$10)) | W5: =IF($B5="","",IF($V5<=0,0,IF($V5<=8000000,$V5*'入力'!$C$65,8000000*'入力'!$C$65+($V5-8000000)*'入力'!$C$66))) | X5: =IF($B5="","",$V5-$W5) | Y5: =IF($B5="","",$X5+$S5+('結果サマリー'!$C$27-'結果サマリー'!$C$9)) | Z5: =IF($B5="","",IF('入力'!$C$5=0,"",1-$Y5/'入力'!$C$5))
A6: 5 | B6: =IF(B5="","",IF(B5+'入力'!$C$71>'入力'!$C$70,"",B5+'入力'!$C$71)) | C6: =IF($B6="","",$B6/12) | D6: =IF($B6="","",IF($B6=0,0,VLOOKUP($C6,'早見表'!$B$3:$D$52,3,TRUE()))) | E6: =IF($B6="","",IF($B6=0,0,VLOOKUP($C6,'早見表'!$G$3:$I$34,3,TRUE()))) | F6: =IF($B6="","",ROUND($D6*('入力'!$C$60+IF('入力'!$C$20="40歳以上64歳以下",'入力'!$C$61,0))/2*12,0)+ROUND($E6*'入力'!$C$62/2*12,0)+ROUND($D6*'入力'!$C$64/2*12,0)) | G6: =IF($B6="","",ROUND($D6*('入力'!$C$60+IF('入力'!$C$20="40歳以上64歳以下",'入力'!$C$61,0))/2*12,0)+ROUND($E6*'入力'!$C$62/2*12,0)+ROUND($E6*'入力'!$C$63*12,0)+ROUND($D6*'入力'!$C$64/2*12,0)) | H6: =IF($B6="","",IF($B6<=2200000,740000,IF($B6<=3600000,$B6*0.3+80000,IF($B6<=6600000,$B6*0.2+440000,IF($B6<=8500000,$B6*0.1+1100000,1950000))))) | I6: =IF($B6="","",MAX($B6-$H6,0)) | J6: =IF($B6="","",$F6+VLOOKUP($I6,'早見表'!$O$3:$P$9,2,TRUE())+IF(AND('入力'!$C$21="有",$I6<=10000000),VLOOKUP('入力'!$E$22,'早見表'!$U$3:$AA$12,IF($I6<=9000000,2,IF($I6<=9500000,3,4)),TRUE()),0)+'入力'!$C$23*'早見表'!$S$5+MAX('入力'!$C$24-'入力'!$C$25,0)*'早見表'!$S$6+IF('入力'!$C$25<=0,0,IF('入力'!$E$26<620001,630000,VLOOKUP('入力'!$E$26,'早見表'!$AD$3:$AF$12,2,TRUE()))*'入力'!$C$25)+'入力'!$C$27*'早見表'!$S$7) | K6: =IF($B6="","",ROUNDDOWN(MAX($I6-$J6,0),-3)) | L6: =IF($B6="","",ROUNDDOWN(MAX($K6*VLOOKUP($K6,'早見表'!$K$3:$M$9,2,TRUE())-VLOOKUP($K6,'早見表'!$K$3:$M$9,3,TRUE()),0),0)) | M6: =IF($B6="","",ROUNDDOWN($L6*0.021,0)) | N6: =IF($B6="","",$L6+$M6) | O6: =IF($B6="","",ROUNDDOWN(MAX($I6-($F6+'早見表'!$S$2+IF(AND('入力'!$C$21="有",$I6<=10000000),VLOOKUP('入力'!$E$22,'早見表'!$U$3:$AA$12,IF($I6<=9000000,5,IF($I6<=9500000,6,7)),TRUE()),0)+'入力'!$C$23*'早見表'!$S$8+MAX('入力'!$C$24-'入力'!$C$25,0)*'早見表'!$S$9+IF('入力'!$C$25<=0,0,IF('入力'!$E$26<620001,450000,VLOOKUP('入力'!$E$26,'早見表'!$AD$3:$AF$12,3,TRUE()))*'入力'!$C$25)+'入力'!$C$27*'早見表'!$S$10),0),-3)*'早見表'!$S$4) | P6: =IF($B6="","",'早見表'!$S$3) | Q6: =IF($B6="","",$O6+$P6) | R6: =IF($B6="","",$F6+$N6+$Q6) | S6: =IF($B6="","",$B6-$R6) | T6: =IF($B6="","",IF($B6=0,"",$S6/$B6)) | U6: =IF($B6="","",$B6+$G6) | V6: =IF($B6="","",'入力'!$C$5-$U6-('結果サマリー'!$C$23-'結果サマリー'!$C$10)) | W6: =IF($B6="","",IF($V6<=0,0,IF($V6<=8000000,$V6*'入力'!$C$65,8000000*'入力'!$C$65+($V6-8000000)*'入力'!$C$66))) | X6: =IF($B6="","",$V6-$W6) | Y6: =IF($B6="","",$X6+$S6+('結果サマリー'!$C$27-'結果サマリー'!$C$9)) | Z6: =IF($B6="","",IF('入力'!$C$5=0,"",1-$Y6/'入力'!$C$5))
A7: 6 | B7: =IF(B6="","",IF(B6+'入力'!$C$71>'入力'!$C$70,"",B6+'入力'!$C$71)) | C7: =IF($B7="","",$B7/12) | D7: =IF($B7="","",IF($B7=0,0,VLOOKUP($C7,'早見表'!$B$3:$D$52,3,TRUE()))) | E7: =IF($B7="","",IF($B7=0,0,VLOOKUP($C7,'早見表'!$G$3:$I$34,3,TRUE()))) | F7: =IF($B7="","",ROUND($D7*('入力'!$C$60+IF('入力'!$C$20="40歳以上64歳以下",'入力'!$C$61,0))/2*12,0)+ROUND($E7*'入力'!$C$62/2*12,0)+ROUND($D7*'入力'!$C$64/2*12,0)) | G7: =IF($B7="","",ROUND($D7*('入力'!$C$60+IF('入力'!$C$20="40歳以上64歳以下",'入力'!$C$61,0))/2*12,0)+ROUND($E7*'入力'!$C$62/2*12,0)+ROUND($E7*'入力'!$C$63*12,0)+ROUND($D7*'入力'!$C$64/2*12,0)) | H7: =IF($B7="","",IF($B7<=2200000,740000,IF($B7<=3600000,$B7*0.3+80000,IF($B7<=6600000,$B7*0.2+440000,IF($B7<=8500000,$B7*0.1+1100000,1950000))))) | I7: =IF($B7="","",MAX($B7-$H7,0)) | J7: =IF($B7="","",$F7+VLOOKUP($I7,'早見表'!$O$3:$P$9,2,TRUE())+IF(AND('入力'!$C$21="有",$I7<=10000000),VLOOKUP('入力'!$E$22,'早見表'!$U$3:$AA$12,IF($I7<=9000000,2,IF($I7<=9500000,3,4)),TRUE()),0)+'入力'!$C$23*'早見表'!$S$5+MAX('入力'!$C$24-'入力'!$C$25,0)*'早見表'!$S$6+IF('入力'!$C$25<=0,0,IF('入力'!$E$26<620001,630000,VLOOKUP('入力'!$E$26,'早見表'!$AD$3:$AF$12,2,TRUE()))*'入力'!$C$25)+'入力'!$C$27*'早見表'!$S$7) | K7: =IF($B7="","",ROUNDDOWN(MAX($I7-$J7,0),-3)) | L7: =IF($B7="","",ROUNDDOWN(MAX($K7*VLOOKUP($K7,'早見表'!$K$3:$M$9,2,TRUE())-VLOOKUP($K7,'早見表'!$K$3:$M$9,3,TRUE()),0),0)) | M7: =IF($B7="","",ROUNDDOWN($L7*0.021,0)) | N7: =IF($B7="","",$L7+$M7) | O7: =IF($B7="","",ROUNDDOWN(MAX($I7-($F7+'早見表'!$S$2+IF(AND('入力'!$C$21="有",$I7<=10000000),VLOOKUP('入力'!$E$22,'早見表'!$U$3:$AA$12,IF($I7<=9000000,5,IF($I7<=9500000,6,7)),TRUE()),0)+'入力'!$C$23*'早見表'!$S$8+MAX('入力'!$C$24-'入力'!$C$25,0)*'早見表'!$S$9+IF('入力'!$C$25<=0,0,IF('入力'!$E$26<620001,450000,VLOOKUP('入力'!$E$26,'早見表'!$AD$3:$AF$12,3,TRUE()))*'入力'!$C$25)+'入力'!$C$27*'早見表'!$S$10),0),-3)*'早見表'!$S$4) | P7: =IF($B7="","",'早見表'!$S$3) | Q7: =IF($B7="","",$O7+$P7) | R7: =IF($B7="","",$F7+$N7+$Q7) | S7: =IF($B7="","",$B7-$R7) | T7: =IF($B7="","",IF($B7=0,"",$S7/$B7)) | U7: =IF($B7="","",$B7+$G7) | V7: =IF($B7="","",'入力'!$C$5-$U7-('結果サマリー'!$C$23-'結果サマリー'!$C$10)) | W7: =IF($B7="","",IF($V7<=0,0,IF($V7<=8000000,$V7*'入力'!$C$65,8000000*'入力'!$C$65+($V7-8000000)*'入力'!$C$66))) | X7: =IF($B7="","",$V7-$W7) | Y7: =IF($B7="","",$X7+$S7+('結果サマリー'!$C$27-'結果サマリー'!$C$9)) | Z7: =IF($B7="","",IF('入力'!$C$5=0,"",1-$Y7/'入力'!$C$5))
A8: 7 | B8: =IF(B7="","",IF(B7+'入力'!$C$71>'入力'!$C$70,"",B7+'入力'!$C$71)) | C8: =IF($B8="","",$B8/12) | D8: =IF($B8="","",IF($B8=0,0,VLOOKUP($C8,'早見表'!$B$3:$D$52,3,TRUE()))) | E8: =IF($B8="","",IF($B8=0,0,VLOOKUP($C8,'早見表'!$G$3:$I$34,3,TRUE()))) | F8: =IF($B8="","",ROUND($D8*('入力'!$C$60+IF('入力'!$C$20="40歳以上64歳以下",'入力'!$C$61,0))/2*12,0)+ROUND($E8*'入力'!$C$62/2*12,0)+ROUND($D8*'入力'!$C$64/2*12,0)) | G8: =IF($B8="","",ROUND($D8*('入力'!$C$60+IF('入力'!$C$20="40歳以上64歳以下",'入力'!$C$61,0))/2*12,0)+ROUND($E8*'入力'!$C$62/2*12,0)+ROUND($E8*'入力'!$C$63*12,0)+ROUND($D8*'入力'!$C$64/2*12,0)) | H8: =IF($B8="","",IF($B8<=2200000,740000,IF($B8<=3600000,$B8*0.3+80000,IF($B8<=6600000,$B8*0.2+440000,IF($B8<=8500000,$B8*0.1+1100000,1950000))))) | I8: =IF($B8="","",MAX($B8-$H8,0)) | J8: =IF($B8="","",$F8+VLOOKUP($I8,'早見表'!$O$3:$P$9,2,TRUE())+IF(AND('入力'!$C$21="有",$I8<=10000000),VLOOKUP('入力'!$E$22,'早見表'!$U$3:$AA$12,IF($I8<=9000000,2,IF($I8<=9500000,3,4)),TRUE()),0)+'入力'!$C$23*'早見表'!$S$5+MAX('入力'!$C$24-'入力'!$C$25,0)*'早見表'!$S$6+IF('入力'!$C$25<=0,0,IF('入力'!$E$26<620001,630000,VLOOKUP('入力'!$E$26,'早見表'!$AD$3:$AF$12,2,TRUE()))*'入力'!$C$25)+'入力'!$C$27*'早見表'!$S$7) | K8: =IF($B8="","",ROUNDDOWN(MAX($I8-$J8,0),-3)) | L8: =IF($B8="","",ROUNDDOWN(MAX($K8*VLOOKUP($K8,'早見表'!$K$3:$M$9,2,TRUE())-VLOOKUP($K8,'早見表'!$K$3:$M$9,3,TRUE()),0),0)) | M8: =IF($B8="","",ROUNDDOWN($L8*0.021,0)) | N8: =IF($B8="","",$L8+$M8) | O8: =IF($B8="","",ROUNDDOWN(MAX($I8-($F8+'早見表'!$S$2+IF(AND('入力'!$C$21="有",$I8<=10000000),VLOOKUP('入力'!$E$22,'早見表'!$U$3:$AA$12,IF($I8<=9000000,5,IF($I8<=9500000,6,7)),TRUE()),0)+'入力'!$C$23*'早見表'!$S$8+MAX('入力'!$C$24-'入力'!$C$25,0)*'早見表'!$S$9+IF('入力'!$C$25<=0,0,IF('入力'!$E$26<620001,450000,VLOOKUP('入力'!$E$26,'早見表'!$AD$3:$AF$12,3,TRUE()))*'入力'!$C$25)+'入力'!$C$27*'早見表'!$S$10),0),-3)*'早見表'!$S$4) | P8: =IF($B8="","",'早見表'!$S$3) | Q8: =IF($B8="","",$O8+$P8) | R8: =IF($B8="","",$F8+$N8+$Q8) | S8: =IF($B8="","",$B8-$R8) | T8: =IF($B8="","",IF($B8=0,"",$S8/$B8)) | U8: =IF($B8="","",$B8+$G8) | V8: =IF($B8="","",'入力'!$C$5-$U8-('結果サマリー'!$C$23-'結果サマリー'!$C$10)) | W8: =IF($B8="","",IF($V8<=0,0,IF($V8<=8000000,$V8*'入力'!$C$65,8000000*'入力'!$C$65+($V8-8000000)*'入力'!$C$66))) | X8: =IF($B8="","",$V8-$W8) | Y8: =IF($B8="","",$X8+$S8+('結果サマリー'!$C$27-'結果サマリー'!$C$9)) | Z8: =IF($B8="","",IF('入力'!$C$5=0,"",1-$Y8/'入力'!$C$5))
